Workbook

Sheet Data
G1: Exch Rate | H1: Adjusted | K1: Exch Rate | L1: Adjusted | O1: Exch Rate | P1: Adjusted
A2: Consecutivo | B2: Fecha | D2: DJIA | F2: FTSE-100 | G2: USD/GBP | H2: FTSE-500 | J2: CAC-40 | K2: EUR/USD | L2: CAC-40 | N2: Nikkei | O2: YEN/USD | P2: Nikkei
A4: 0 | B4: 38936 | D4: 11219.38 | F4: 5828.8 | G4: 1.9098 | H4: =F4*G4 -> 11131.842 | J4: 4956.34 | K4: 0.7776 | L4: =J4/K4 -> 6373.894 | N4: 15154.06 | O4: 115 | P4: =N4/O4 -> 131.77443
A5: 1 | B5: 38937 | D5: 11173.59 | F5: 5818.1 | G5: 1.9072 | H5: =F5*G5 -> 11096.28 | J5: 4967.95 | K5: 0.7789 | L5: =J5/K5 -> 6378.1615 | N5: 15464.66 | O5: 115.08 | P5: =N5/O5 -> 134.38182
A6: 2 | B6: 38938 | D6: 11076.18 | F6: 5860.5 | G6: 1.9086 | H6: =F6*G6 -> 11185.35 | J6: 5025.15 | K6: 0.7762 | L6: =J6/K6 -> 6474.0402 | N6: 15656.59 | O6: 115.17 | P6: =N6/O6 -> 135.9433
A7: 3 | B7: 38939 | D7: 11124.37 | F7: 5823.4 | G7: 1.8918 | H7: =F7*G7 -> 11016.708 | J7: 4976.64 | K7: 0.7828 | L7: =J7/K7 -> 6357.4859 | N7: 15630.91 | O7: 115.41 | P7: =N7/O7 -> 135.43809
A8: 4 | B8: 38940 | D8: 11088.02 | F8: 5820.1 | G8: 1.897 | H8: =F8*G8 -> 11040.73 | J8: 4985.52 | K8: 0.7833 | L8: =J8/K8 -> 6364.7645 | N8: 15565.02 | O8: 116.07 | P8: =N8/O8 -> 134.10028
A9: 5 | B9: 38943 | D9: 11097.87 | F9: 5870.9 | G9: 1.8923 | H9: =F9*G9 -> 11109.504 | J9: 5046.93 | K9: 0.7847 | L9: =J9/K9 -> 6431.6682 | N9: 15857.11 | O9: 116.45 | P9: =N9/O9 -> 136.17097
A10: 6 | B10: 38944 | D10: 11230.26 | F10: 5897.9 | G10: 1.8955 | H10: =F10*G10 -> 11179.469 | J10: 5115.02 | K10: 0.782 | L10: =J10/K10 -> 6540.9463 | N10: 15816.19 | O10: 116.02 | P10: =N10/O10 -> 136.32296
A11: 7 | B11: 38945 | D11: 11327.12 | F11: 5896.6 | G11: 1.9 | H11: =F11*G11 -> 11203.54 | J11: 5137.31 | K11: 0.778 | L11: =J11/K11 -> 6603.2262 | N11: 16071.36 | O11: 115.78 | P11: =N11/O11 -> 138.80947
A12: 8 | B12: 38946 | D12: 11334.96 | F12: 5900.4 | G12: 1.8931 | H12: =F12*G12 -> 11170.047 | J12: 5144.84 | K12: 0.7775 | L12: =J12/K12 -> 6617.1576 | N12: 16020.84 | O12: 115.53 | P12: =N12/O12 -> 138.67255
A13: 9 | B13: 38947 | D13: 11381.47 | F13: 5903.4 | G13: 1.8796 | H13: =F13*G13 -> 11096.031 | J13: 5135.69 | K13: 0.78 | L13: =J13/K13 -> 6584.2179 | N13: 16105.98 | O13: 115.74 | P13: =N13/O13 -> 139.15656
A14: 10 | B14: 38950 | D14: 11345.04 | F14: 5915.2 | G14: 1.897 | H14: =F14*G14 -> 11221.134 | J14: 5104.65 | K14: 0.7741 | L14: =J14/K14 -> 6594.3031 | N14: 15969.04 | O14: 115.86 | P14: =N14/O14 -> 137.83049
A15: 11 | B15: 38951 | D15: 11339.84 | F15: 5902.6 | G15: 1.8885 | H15: =F15*G15 -> 11147.06 | J15: 5128.33 | K15: 0.7804 | L15: =J15/K15 -> 6571.4121 | N15: 16181.17 | O15: 116.46 | P15: =N15/O15 -> 138.94187
... A504: 500 | B504: 39716 | D504: 11022.06 | F504: 5197 | G504: 1.8472 | H504: =F504*G504 -> 9599.8984 | J504: 4226.81 | K504: 0.6817 | L504: =J504/K504 -> 6200.3961 | N504: 12006.53 | O504: 106.42 | P504: =N504/O504 -> 112.82212

Sheet Escenarios
A1: Scenario | B1: DJIA | C1: FTSE 100 | D1: CAC 40 | E1: Nikkei 225 | H1: P t+1 | J1: DP al 26/09/08 | K1: DP% al 26/09/08 | M1: P t | N1: DJIA | O1: FTSE 100 | P1: CAC40 | Q1: Nikkei 225
A2: 1 | B2: =Data!D5/Data!D4 -> 0.99591867 | C2: =Data!H5/Data!H4 -> 0.99680539 | D2: =Data!L5/Data!L4 -> 1.0006695 | E2: =Data!P5/Data!P4 -> 1.0197867 | F2: =F$503^G2 -> 0.0066368516 | G2: 499 | H2: =$N$2*B2+$O$2*C2+$P$2*D2+$Q$2*E2 -> 10014334 | J2: =H2-SUM($N$2:$Q$2) -> 14333.846 | K2: =(H2/$R$2)-1 -> 0.0014333846 | M2: Investments | N2: 4000000 | O2: 3000000 | P2: 1000000 | Q2: 2000000 | R2: =SUM(N2:Q2) -> 10000000
A3: 2 | B3: =Data!D6/Data!D5 -> 0.99128212 | C3: =Data!H6/Data!H5 -> 1.008027 | D3: =Data!L6/Data!L5 -> 1.0150323 | E3: =Data!P6/Data!P5 -> 1.0116197 | F3: =F$503^G3 -> 0.0067038905 | G3: 498 | H3: =$N$2*B3+$O$2*C3+$P$2*D3+$Q$2*E3 -> 10027481 | J3: =H3-SUM($N$2:$Q$2) -> 27481.313 | K3: =(H3/$R$2)-1 -> 0.0027481313
A4: 3 | B4: =Data!D7/Data!D6 -> 1.0043508 | C4: =Data!H7/Data!H6 -> 0.98492294 | D4: =Data!L7/Data!L6 -> 0.98199668 | E4: =Data!P7/Data!P6 -> 0.99628366 | F4: =F$503^G4 -> 0.0067716065 | G4: 497 | H4: =$N$2*B4+$O$2*C4+$P$2*D4+$Q$2*E4 -> 9946735.9 | J4: =H4-SUM($N$2:$Q$2) -> -53264.059 | K4: =(H4/$R$2)-1 -> -0.0053264059
A5: 4 | B5: =Data!D8/Data!D7 -> 0.9967324 | C5: =Data!H8/Data!H7 -> 1.0021805 | D5: =Data!L8/Data!L7 -> 1.0011449 | E5: =Data!P8/Data!P7 -> 0.99012238 | F5: =F$503^G5 -> 0.0068400066 | G5: 496 | H5: =$N$2*B5+$O$2*C5+$P$2*D5+$Q$2*E5 -> 9974860.6 | J5: =H5-SUM($N$2:$Q$2) -> -25139.366 | K5: =(H5/$R$2)-1 -> -0.0025139366
A6: 5 | B6: =Data!D9/Data!D8 -> 1.0008883 | C6: =Data!H9/Data!H8 -> 1.0062292 | D6: =Data!L9/Data!L8 -> 1.0105116 | E6: =Data!P9/Data!P8 -> 1.0154414 | F6: =F$503^G6 -> 0.0069090976 | G6: 495 | H6: =$N$2*B6+$O$2*C6+$P$2*D6+$Q$2*E6 -> 10063635 | J6: =H6-SUM($N$2:$Q$2) -> 63635.125 | K6: =(H6/$R$2)-1 -> 0.0063635125
A7: 6 | B7: =Data!D10/Data!D9 -> 1.0119293 | C7: =Data!H10/Data!H9 -> 1.0062978 | D7: =Data!L10/Data!L9 -> 1.0169906 | E7: =Data!P10/Data!P9 -> 1.0011161 | F7: =F$503^G7 -> 0.0069788864 | G7: 494 | H7: =$N$2*B7+$O$2*C7+$P$2*D7+$Q$2*E7 -> 10085834 | J7: =H7-SUM($N$2:$Q$2) -> 85833.582 | K7: =(H7/$R$2)-1 -> 0.0085833582
A8: 7 | B8: =Data!D11/Data!D10 -> 1.0086249 | C8: =Data!H11/Data!H10 -> 1.0021531 | D8: =Data!L11/Data!L10 -> 1.0095215 | E8: =Data!P11/Data!P10 -> 1.0182398 | F8: =F$503^G8 -> 0.0070493802 | G8: 493 | H8: =$N$2*B8+$O$2*C8+$P$2*D8+$Q$2*E8 -> 10086960 | J8: =H8-SUM($N$2:$Q$2) -> 86960.119 | K8: =(H8/$R$2)-1 -> 0.0086960119
A9: 8 | B9: =Data!D12/Data!D11 -> 1.0006921 | C9: =Data!H12/Data!H11 -> 0.99701052 | D9: =Data!L12/Data!L11 -> 1.0021098 | E9: =Data!P12/Data!P11 -> 0.99901366 | F9: =F$503^G9 -> 0.0071205861 | G9: 492 | H9: =$N$2*B9+$O$2*C9+$P$2*D9+$Q$2*E9 -> 9993937.2 | J9: =H9-SUM($N$2:$Q$2) -> -6062.7712 | K9: =(H9/$R$2)-1 -> -0.00060627712
A10: 9 | B10: =Data!D13/Data!D12 -> 1.0041032 | C10: =Data!H13/Data!H12 -> 0.99337365 | D10: =Data!L13/Data!L12 -> 0.99502209 | E10: =Data!P13/Data!P12 -> 1.0034903 | F10: =F$503^G10 -> 0.0071925112 | G10: 491 | H10: =$N$2*B10+$O$2*C10+$P$2*D10+$Q$2*E10 -> 9998536.5 | J10: =H10-SUM($N$2:$Q$2) -> -1463.4609 | K10: =(H10/$R$2)-1 -> -0.00014634609
A11: 10 | B11: =Data!D14/Data!D13 -> 0.99679918 | C11: =Data!H14/Data!H13 -> 1.0112746 | D11: =Data!L14/Data!L13 -> 1.0015317 | E11: =Data!P14/Data!P13 -> 0.99047064 | F11: =F$503^G11 -> 0.0072651628 | G11: 490 | H11: =$N$2*B11+$O$2*C11+$P$2*D11+$Q$2*E11 -> 10003494 | J11: =H11-SUM($N$2:$Q$2) -> 3493.6484 | K11: =(H11/$R$2)-1 -> 0.00034936484
A12: 11 | B12: =Data!D15/Data!D14 -> 0.99954165 | C12: =Data!H15/Data!H14 -> 0.99339868 | D12: =Data!L15/Data!L14 -> 0.99652868 | E12: =Data!P15/Data!P14 -> 1.0080634 | F12: =F$503^G12 -> 0.0073385483 | G12: 489 | H12: =$N$2*B12+$O$2*C12+$P$2*D12+$Q$2*E12 -> 9991018.1 | J12: =H12-SUM($N$2:$Q$2) -> -8981.8698 | K12: =(H12/$R$2)-1 -> -0.00089818698
A13: 12 | B13: =Data!D16/Data!D15 -> 0.99630154 | C13: =Data!H16/Data!H15 -> 0.99551648 | D13: =Data!L16/Data!L15 -> 0.98958656 | E13: =Data!P16/Data!P15 -> 0.99827891 | F13: =F$503^G13 -> 0.0074126751 | G13: 488 | H13: =$N$2*B13+$O$2*C13+$P$2*D13+$Q$2*E13 -> 9957900 | J13: =H13-SUM($N$2:$Q$2) -> -42100.045 | K13: =(H13/$R$2)-1 -> -0.0042100045
A14: 13 | B14: =Data!D17/Data!D16 -> 1.0005806 | C14: =Data!H17/Data!H16 -> 1.0003365 | D14: =Data!L17/Data!L16 -> 1.0059259 | E14: =Data!P17/Data!P16 -> 0.98925973 | F14: =F$503^G14 -> 0.0074875506 | G14: 487 | H14: =$N$2*B14+$O$2*C14+$P$2*D14+$Q$2*E14 -> 9987777.4 | J14: =H14-SUM($N$2:$Q$2) -> -12222.646 | K14: =(H14/$R$2)-1 -> -0.0012222646
A15: 14 | B15: =Data!D18/Data!D17 -> 0.99819452 | C15: =Data!H18/Data!H17 -> 0.99886491 | D15: =Data!L18/Data!L17 -> 0.99596821 | E15: =Data!P18/Data!P17 -> 0.99028096 | F15: =F$503^G15 -> 0.0075631824 | G15: 486 | H15: =$N$2*B15+$O$2*C15+$P$2*D15+$Q$2*E15 -> 9965902.9 | J15: =H15-SUM($N$2:$Q$2) -> -34097.058 | K15: =(H15/$R$2)-1 -> -0.0034097058 | N15: Clase | O15: Frecuencia
A16: 15 | B16: =Data!D19/Data!D18 -> 1.0076116 | C16: =Data!H19/Data!H18 -> 1.005208 | D16: =Data!L19/Data!L18 -> 1.0105258 | E16: =Data!P19/Data!P18 -> 1.0002225 | F16: =F$503^G16 -> 0.0076395782 | G16: 485 | H16: =$N$2*B16+$O$2*C16+$P$2*D16+$Q$2*E16 -> 10057041 | J16: =H16-SUM($N$2:$Q$2) -> 57041.294 | K16: =(H16/$R$2)-1 -> 0.0057041294 | N16: -0.0477841 | O16: 1
A17: 16 | B17: =Data!D20/Data!D19 -> 1.0011407 | C17: =Data!H20/Data!H19 -> 1.0138785 | D17: =Data!L20/Data!L19 -> 1.0102836 | E17: =Data!P20/Data!P19 -> 0.99772393 | F17: =F$503^G17 -> 0.0077167456 | G17: 484 | H17: =$N$2*B17+$O$2*C17+$P$2*D17+$Q$2*E17 -> 10051930 | J17: =H17-SUM($N$2:$Q$2) -> 51929.993 | K17: =(H17/$R$2)-1 -> 0.0051929993 | N17: -0.043085753 | O17: 0
A18: 17 | B18: =Data!D21/Data!D20 -> 0.99984538 | C18: =Data!H21/Data!H20 -> 0.99394443 | D18: =Data!L21/Data!L20 -> 0.99389658 | E18: =Data!P21/Data!P20 -> 1.0147643 | F18: =F$503^G18 -> 0.0077946926 | G18: 483 | H18: =$N$2*B18+$O$2*C18+$P$2*D18+$Q$2*E18 -> 10004640 | J18: =H18-SUM($N$2:$Q$2) -> 4640.0186 | K18: =(H18/$R$2)-1 -> 0.00046400186 | N18: -0.038387405 | O18: 0
A19: 18 | B19: =Data!D22/Data!D21 -> 1.0072928 | C19: =Data!H22/Data!H21 -> 1.008128 | D19: =Data!L22/Data!L21 -> 1.0039498 | E19: =Data!P22/Data!P21 -> 0.99942627 | F19: =F$503^G19 -> 0.0078734268 | G19: 482 | H19: =$N$2*B19+$O$2*C19+$P$2*D19+$Q$2*E19 -> 10056358 | J19: =H19-SUM($N$2:$Q$2) -> 56357.543 | K19: =(H19/$R$2)-1 -> 0.0056357543 | N19: -0.033689058 | O19: 1
A20: 19 | B20: =Data!D23/Data!D22 -> 1.0004475 | C20: =Data!H23/Data!H22 -> 0.99977467 | D20: =Data!L23/Data!L22 -> 0.99821065 | E20: =Data!P23/Data!P22 -> 1.0262731 | F20: =F$503^G20 -> 0.0079529564 | G20: 481 | H20: =$N$2*B20+$O$2*C20+$P$2*D20+$Q$2*E20 -> 10051871 | J20: =H20-SUM($N$2:$Q$2) -> 51870.781 | K20: =(H20/$R$2)-1 -> 0.0051870781 | N20: -0.028990711 | O20: 0
A21: 20 | B21: =Data!D24/Data!D23 -> 0.99450009 | C21: =Data!H24/Data!H23 -> 0.98495501 | D21: =Data!L24/Data!L23 -> 0.98739961 | E21: =Data!P24/Data!P23 -> 0.98926706 | F21: =F$503^G21 -> 0.0080332893 | G21: 480 | H21: =$N$2*B21+$O$2*C21+$P$2*D21+$Q$2*E21 -> 9898799.1 | J21: =H21-SUM($N$2:$Q$2) -> -101200.88 | K21: =(H21/$R$2)-1 -> -0.010120088 | N21: -0.024292363 | O21: 3
A22: 21 | B22: =Data!D25/Data!D24 -> 0.99344567 | C22: =Data!H25/Data!H24 -> 0.98452446 | D22: =Data!L25/Data!L24 -> 0.98488225 | E22: =Data!P25/Data!P24 -> 0.98483617 | F22: =F$503^G22 -> 0.0081144336 | G22: 479 | H22: =$N$2*B22+$O$2*C22+$P$2*D22+$Q$2*E22 -> 9881910.7 | J22: =H22-SUM($N$2:$Q$2) -> -118089.34 | K22: =(H22/$R$2)-1 -> -0.011808934 | N22: -0.019594016 | O22: 3
A23: 22 | B23: =Data!D26/Data!D25 -> 1.0053541 | C23: =Data!H26/Data!H25 -> 0.99885253 | D23: =Data!L26/Data!L25 -> 0.99770973 | E23: =Data!P26/Data!P25 -> 1.0017551 | F23: =F$503^G23 -> 0.0081963976 | G23: 478 | H23: =$N$2*B23+$O$2*C23+$P$2*D23+$Q$2*E23 -> 10019194 | J23: =H23-SUM($N$2:$Q$2) -> 19194.093 | K23: =(H23/$R$2)-1 -> 0.0019194093 | N23: -0.014895669 | O23: 20
A24: 23 | B24: =Data!D27/Data!D26 -> 1.0004152 | C24: =Data!H27/Data!H26 -> 0.99376521 | D24: =Data!L27/Data!L26 -> 0.99876379 | E24: =Data!P27/Data!P26 -> 0.97386727 | F24: =F$503^G24 -> 0.0082791895 | G24: 477 | H24: =$N$2*B24+$O$2*C24+$P$2*D24+$Q$2*E24 -> 9929454.8 | J24: =H24-SUM($N$2:$Q$2) -> -70545.223 | K24: =(H24/$R$2)-1 -> -0.0070545223 | N24: -0.010197321 | O24: 40
A25: 24 | B25: =Data!D28/Data!D27 -> 1.008884 | C25: =Data!H28/Data!H27 -> 1.0147273 | D25: =Data!L28/Data!L27 -> 1.0131188 | E25: =Data!P28/Data!P27 -> 0.99499542 | F25: =F$503^G25 -> 0.0083628177 | G25: 476 | H25: =$N$2*B25+$O$2*C25+$P$2*D25+$Q$2*E25 -> 10082828 | J25: =H25-SUM($N$2:$Q$2) -> 82827.667 | K25: =(H25/$R$2)-1 -> 0.0082827667 | N25: -0.0054989741 | O25: 52
A26: 25 | B26: =Data!D29/Data!D28 -> 1.0039337 | C26: =Data!H29/Data!H28 -> 0.99890739 | D26: =Data!L29/Data!L28 -> 1.0014437 | E26: =Data!P29/Data!P28 -> 1.0028051 | F26: =F$503^G26 -> 0.0084472906 | G26: 475 | H26: =$N$2*B26+$O$2*C26+$P$2*D26+$Q$2*E26 -> 10019511 | J26: =H26-SUM($N$2:$Q$2) -> 19510.948 | K26: =(H26/$R$2)-1 -> 0.0019510948 | N26: -0.00080062681 | O26: 89
A27: 26 | B27: =Data!D30/Data!D29 -> 0.99861998 | C27: =Data!H30/Data!H29 -> 1.0060209 | D27: =Data!L30/Data!L29 -> 1.0029815 | E27: =Data!P30/Data!P29 -> 1.0144535 | F27: =F$503^G27 -> 0.0085326167 | G27: 474 | H27: =$N$2*B27+$O$2*C27+$P$2*D27+$Q$2*E27 -> 10044431 | J27: =H27-SUM($N$2:$Q$2) -> 44431.147 | K27: =(H27/$R$2)-1 -> 0.0044431147 | N27: 0.0038977205 | O27: 133
... A37: 36 | B37: =Data!D40/Data!D39 -> 0.99663949 | C37: =Data!H40/Data!H39 -> 0.99531138 | D37: =Data!L40/Data!L39 -> 0.99822673 | E37: =Data!P40/Data!P39 -> 1.0043653 | F37: =F$503^G37 -> 0.0094347478 | G37: 464 | H37: =$N$2*B37+$O$2*C37+$P$2*D37+$Q$2*E37 -> 9979449.4 | J37: =H37-SUM($N$2:$Q$2) -> -20550.596 | K37: =(H37/$R$2)-1 -> -0.0020550596 | N37: 0.050881194 | O37: 0
A38: 37 | B38: =Data!D41/Data!D40 -> 0.99925337 | C38: =Data!H41/Data!H40 -> 1.0084848 | D38: =Data!L41/Data!L40 -> 1.0047985 | E38: =Data!P41/Data!P40 -> 1.0109386 | F38: =F$503^G38 -> 0.0095300482 | G38: 463 | H38: =$N$2*B38+$O$2*C38+$P$2*D38+$Q$2*E38 -> 10049144 | J38: =H38-SUM($N$2:$Q$2) -> 49143.549 | K38: =(H38/$R$2)-1 -> 0.0049143549 | N38: y mayor... | O38: 1
A39: 38 | B39: =Data!D42/Data!D41 -> 1.0048833 | C39: =Data!H42/Data!H41 -> 0.99869307 | D39: =Data!L42/Data!L41 -> 0.99529479 | E39: =Data!P42/Data!P41 -> 0.99789325 | F39: =F$503^G39 -> 0.0096263113 | G39: 462 | H39: =$N$2*B39+$O$2*C39+$P$2*D39+$Q$2*E39 -> 10006694 | J39: =H39-SUM($N$2:$Q$2) -> 6693.7643 | K39: =(H39/$R$2)-1 -> 0.00066937643
A40: 39 | B40: =Data!D43/Data!D42 -> 1.0105113 | C40: =Data!H43/Data!H42 -> 1.002292 | D40: =Data!L43/Data!L42 -> 1.0029534 | E40: =Data!P43/Data!P42 -> 0.98942202 | F40: =F$503^G40 -> 0.0097235468 | G40: 461 | H40: =$N$2*B40+$O$2*C40+$P$2*D40+$Q$2*E40 -> 10030719 | J40: =H40-SUM($N$2:$Q$2) -> 30718.954 | K40: =(H40/$R$2)-1 -> 0.0030718954
A41: 40 | B41: =Data!D44/Data!D43 -> 1.0013569 | C41: =Data!H44/Data!H43 -> 1.0025231 | D41: =Data!L44/Data!L43 -> 1.0060838 | E41: =Data!P44/Data!P43 -> 1.0253264 | F41: =F$503^G41 -> 0.0098217645 | G41: 460 | H41: =$N$2*B41+$O$2*C41+$P$2*D41+$Q$2*E41 -> 10069733 | J41: =H41-SUM($N$2:$Q$2) -> 69733.475 | K41: =(H41/$R$2)-1 -> 0.0069733475
A42: 41 | B42: =Data!D45/Data!D44 -> 0.99861124 | C42: =Data!H45/Data!H44 -> 0.99561641 | D42: =Data!L45/Data!L44 -> 0.99073107 | E42: =Data!P45/Data!P44 -> 0.98827681 | F42: =F$503^G42 -> 0.0099209742 | G42: 459 | H42: =$N$2*B42+$O$2*C42+$P$2*D42+$Q$2*E42 -> 9948578.9 | J42: =H42-SUM($N$2:$Q$2) -> -51421.138 | K42: =(H42/$R$2)-1 -> -0.0051421138
A43: 42 | B43: =Data!D46/Data!D45 -> 1.0014312 | C43: =Data!H46/Data!H45 -> 1.0043372 | D43: =Data!L46/Data!L45 -> 1.0014683 | E43: =Data!P46/Data!P45 -> 0.99697616 | F43: =F$503^G43 -> 0.010021186 | G43: 458 | H43: =$N$2*B43+$O$2*C43+$P$2*D43+$Q$2*E43 -> 10014157 | J43: =H43-SUM($N$2:$Q$2) -> 14157.178 | K43: =(H43/$R$2)-1 -> 0.0014157178
A44: 43 | B44: =Data!D47/Data!D46 -> 0.99873264 | C44: =Data!H47/Data!H46 -> 1.0005629 | D44: =Data!L47/Data!L46 -> 1.0013937 | E44: =Data!P47/Data!P46 -> 0.99584569 | F44: =F$503^G44 -> 0.01012241 | G44: 457 | H44: =$N$2*B44+$O$2*C44+$P$2*D44+$Q$2*E44 -> 9989704.4 | J44: =H44-SUM($N$2:$Q$2) -> -10295.647 | K44: =(H44/$R$2)-1 -> -0.0010295647
A45: 44 | B45: =Data!D48/Data!D47 -> 1.0080635 | C45: =Data!H48/Data!H47 -> 1.0079245 | D45: =Data!L48/Data!L47 -> 1.0082087 | E45: =Data!P48/Data!P47 -> 0.99873159 | F45: =F$503^G45 -> 0.010224657 | G45: 456 | H45: =$N$2*B45+$O$2*C45+$P$2*D45+$Q$2*E45 -> 10061700 | J45: =H45-SUM($N$2:$Q$2) -> 61699.658 | K45: =(H45/$R$2)-1 -> 0.0061699658
A46: 45 | B46: =Data!D49/Data!D48 -> 1.0010722 | C46: =Data!H49/Data!H48 -> 1.0052851 | D46: =Data!L49/Data!L48 -> 0.99496281 | E46: =Data!P49/Data!P48 -> 1.0072129 | F46: =F$503^G46 -> 0.010327936 | G46: 455 | H46: =$N$2*B46+$O$2*C46+$P$2*D46+$Q$2*E46 -> 10029533 | J46: =H46-SUM($N$2:$Q$2) -> 29532.716 | K46: =(H46/$R$2)-1 -> 0.0029532716
A47: 46 | B47: =Data!D50/Data!D49 -> 1.0016789 | C47: =Data!H50/Data!H49 -> 1.0049916 | D47: =Data!L50/Data!L49 -> 1.0033877 | E47: =Data!P50/Data!P49 -> 1.0146952 | F47: =F$503^G47 -> 0.010432259 | G47: 454 | H47: =$N$2*B47+$O$2*C47+$P$2*D47+$Q$2*E47 -> 10054468 | J47: =H47-SUM($N$2:$Q$2) -> 54468.401 | K47: =(H47/$R$2)-1 -> 0.0054468401
A48: 47 | B48: =Data!D51/Data!D50 -> 0.99744837 | C48: =Data!H51/Data!H50 -> 0.99450505 | D48: =Data!L51/Data!L50 -> 0.9908605 | E48: =Data!P51/Data!P50 -> 0.99974841 | F48: =F$503^G48 -> 0.010537635 | G48: 453 | H48: =$N$2*B48+$O$2*C48+$P$2*D48+$Q$2*E48 -> 9963666 | J48: =H48-SUM($N$2:$Q$2) -> -36334.046 | K48: =(H48/$R$2)-1 -> -0.0036334046 | N48: Bin | O48: Frequency
A49: 48 | B49: =Data!D52/Data!D51 -> 1.0035699 | C49: =Data!H52/Data!H51 -> 1.005604 | D49: =Data!L52/Data!L51 -> 1.0089695 | E49: =Data!P52/Data!P51 -> 0.99929375 | F49: =F$503^G49 -> 0.010644076 | G49: 452 | H49: =$N$2*B49+$O$2*C49+$P$2*D49+$Q$2*E49 -> 10038648 | J49: =H49-SUM($N$2:$Q$2) -> 38648.464 | K49: =(H49/$R$2)-1 -> 0.0038648464 | N49: -477841 | O49: 1
...

Sheet VaR 1 Sim Hist
A1: Scenario | B1: Ganancias/Pérdidas del P al 26/09/08
A2: 494 | B2: -477841 | D2: Confianza = | E2: 0.99
A3: 339 | B3: -345435.08 | D3: Cuantil = | E3: =COUNT(B2:B501)*(1-E2) -> 5 | F3: =_xlfn.FORMULATEXT(E3) -> =COUNT(B2:B501)*(1-E2)
A4: 349 | B4: -282203.85 | D4: VaR99%, 1 día (USD) = | E4: =ABS(SMALL(B2:B501,E3)) -> 253384.96 | F4: =_xlfn.FORMULATEXT(E4) -> =ABS(SMALL(B2:B501,E3))
A5: 329 | B5: -277041.29 | D5: VaR99%, 1 día (%P) = | E5: =E4/Escenarios!$R$2 -> 0.025338496 | F5: =_xlfn.FORMULATEXT(E5) -> =E4/Escenarios!$R$2
A6: 487 | B6: -253384.96 | D6: CVaR99%, 1 día (USD) = | E6: =ABS(AVERAGE(B2:B5)) -> 345630.3 | F6: =_xlfn.FORMULATEXT(E6) -> =ABS(AVERAGE(B2:B5))
A7: 227 | B7: -217973.96 | D7: CVaR99%, 1 día (%P) = | E7: =E6/Escenarios!$R$2 -> 0.03456303 | F7: =_xlfn.FORMULATEXT(E7) -> =E6/Escenarios!$R$2
A8: 131 | B8: -202255.54 | D8: N = | E8: 10
A9: 238 | B9: -201389.22 | D9: VaR99%, 10 días = | E9: =E4*SQRT(E8) -> 801273.59 | F9: =_xlfn.FORMULATEXT(E9) -> =E4*SQRT(E8)
A10: 473 | B10: -191269.07 | D10: VaR99%, 10 días (%P) = | E10: =E9/Escenarios!$R$2 -> 0.080127359 | F10: =_xlfn.FORMULATEXT(E10) -> =E9/Escenarios!$R$2
A11: 306 | B11: -191049.66
A12: 477 | B12: -185126.95 | D12: Aplicación regulatoria:
A13: 495 | B13: -184449.63 | D13: CapitalRiesgo de mercado (USD) = | E13: =3*E9 -> 2403820.8 | F13: =_xlfn.FORMULATEXT(E13) -> =3*E9
A14: 376 | B14: -182707.22 | D14: CapitalRiesgo de mercado (%P) = | E14: =E13/Escenarios!$R$2 -> 0.24038208 | F14: =_xlfn.FORMULATEXT(E14) -> =E13/Escenarios!$R$2
A15: 237 | B15: -180104.75
A16: 365 | B16: -172223.74 | D16: Ojo: solo faltaría la ponderación por calidad crediticia de los activos en los que se invierten.
A17: 283 | B17: -172211.95
A18: 378 | B18: -167104.18
A19: 320 | B19: -167065.85
A20: 242 | B20: -166799.71
A21: 322 | B21: -166516.54
A22: 441 | B22: -164074.87
A23: 304 | B23: -160777.76
A24: 292 | B24: -157596.97
A25: 485 | B25: -156829.86
A26: 490 | B26: -156511.17
A27: 249 | B27: -152981.56
A28: 370 | B28: -152585.4
... A501: 497 | B501: 555795.41
B503: =AVERAGE(B2:B501) -> -870.09614
B504: =STDEV(B2:B501) -> 93698.408
B505: =NORMINV(0.99,B503,B504) -> 217105
B506: =NORMDIST(B505, B503,B504,FALSE) -> 2.8444605e-07
B507: =(1/B506)*SQRT(0.01*0.99/500) -> 15643.455
B508: =KURT(B2:B501) -> 4.2197048

Sheet VaR 2 Sim MC
D1: Adjusted | E1: Adjusted | F1: Adjusted | H1: m = | I1: =AVERAGE(I5:I504) -> -3.5487842e-05 | J1: =AVERAGE(J5:J504) -> -0.00029611431 | K1: =AVERAGE(K5:K504) -> -5.5194838e-05 | L1: =AVERAGE(L5:L504) -> -0.00031055843 | N1: Precios en t+1 simulados por MC | S1: Portfolio | T1: DJIA | U1: FTSE 100 | V1: CAC40 | W1: Nikkei 225
A2: Consecutivo | B2: Fecha | C2: DJIA | D2: FTSE-500 | E2: CAC-40 | F2: Nikkei | H2: s2 = | I2: =_xlfn.VAR.P(I5:I504) -> 0.00012310021 | J2: =_xlfn.VAR.P(J5:J504) -> 0.00020062422 | K2: =_xlfn.VAR.P(K5:K504) -> 0.0001940675 | L2: =_xlfn.VAR.P(L5:L504) -> 0.00019284344 | N2: DJIA | O2: FTSE-500 | P2: CAC-40 | Q2: Nikkei | S2: Investments | T2: 4000000 | U2: 3000000 | V2: 1000000 | W2: 2000000 | X2: =SUM(T2:W2) -> 10000000
H3: s = | I3: =_xlfn.STDEV.P(I5:I504) -> 0.011095053 | J3: =_xlfn.STDEV.P(J5:J504) -> 0.014164188 | K3: =_xlfn.STDEV.P(K5:K504) -> 0.013930811 | L3: =_xlfn.STDEV.P(L5:L504) -> 0.013886808
A4: 0 | B4: 38936 | C4: 11219.38 | D4: 11131.842 | E4: 6373.894 | F4: 131.77443 | T4: Pt+1 | V4: DPt+1 | X4: DPt+1 (Ordenado)
A5: 1 | B5: 38937 | C5: 11173.59 | D5: 11096.28 | E5: 6378.1615 | F5: 134.38182 | I5: =LN(C5/C4) -> -0.0040896821 | J5: =LN(D5/D4) -> -0.003199726 | K5: =LN(E5/E4) -> 0.00066930026 | L5: =LN(F5/F4) -> 0.019593528 | N5: =C$504*EXP((I$1-I$2/2)*(1)+I$3*_xlfn.NORM.S.INV(RAND())*SQRT(1)) -> 10978.766 | O5: =D$504*EXP((J$1-J$2/2)*(1)+J$3*_xlfn.NORM.S.INV(RAND())*SQRT(1)) -> 9671.9498 | P5: =E$504*EXP((K$1-K$2/2)*(1)+K$3*_xlfn.NORM.S.INV(RAND())*SQRT(1)) -> 6209.859 | Q5: =F$504*EXP((L$1-L$2/2)*(1)+L$3*_xlfn.NORM.S.INV(RAND())*SQRT(1)) -> 110.51279 | T5: =N5/C$504*T$2+O5/D$504*U$2+P5/E$504*V$2+Q5/F$504*W$2 -> 9967393.4 | V5: =T5-X$2 -> -32606.606 | X5: -230377.81 | Z5: Confianza = | AA5: 0.99
A6: 2 | B6: 38938 | C6: 11076.18 | D6: 11185.35 | E6: 6474.0402 | F6: 135.9433 | I6: =LN(C6/C5) -> -0.0087561015 | J6: =LN(D6/D5) -> 0.0079949673 | K6: =LN(E6/E5) -> 0.014920473 | L6: =LN(F6/F5) -> 0.011552735 | N6: =C$504*EXP((I$1-I$2/2)*(1)+I$3*_xlfn.NORM.S.INV(RAND())*SQRT(1)) -> 11099.257 | O6: =D$504*EXP((J$1-J$2/2)*(1)+J$3*_xlfn.NORM.S.INV(RAND())*SQRT(1)) -> 9733.5035 | P6: =E$504*EXP((K$1-K$2/2)*(1)+K$3*_xlfn.NORM.S.INV(RAND())*SQRT(1)) -> 6074.7432 | Q6: =F$504*EXP((L$1-L$2/2)*(1)+L$3*_xlfn.NORM.S.INV(RAND())*SQRT(1)) -> 109.65596 | T6: =N6/C$504*T$2+O6/D$504*U$2+P6/E$504*V$2+Q6/F$504*W$2 -> 9993375.8 | V6: =T6-X$2 -> -6624.2032 | X6: -216588.15 | Z6: Cuantil = | AA6: =COUNT(X5:X504)*(1-AA5) -> 5
A7: 3 | B7: 38939 | C7: 11124.37 | D7: 11016.708 | E7: 6357.4859 | F7: 135.43809 | I7: =LN(C7/C6) -> 0.0043413407 | J7: =LN(D7/D6) -> -0.015191873 | K7: =LN(E7/E6) -> -0.018167356 | L7: =LN(F7/F6) -> -0.0037232583 | N7: =C$504*EXP((I$1-I$2/2)*(1)+I$3*_xlfn.NORM.S.INV(RAND())*SQRT(1)) -> 10993.572 | O7: =D$504*EXP((J$1-J$2/2)*(1)+J$3*_xlfn.NORM.S.INV(RAND())*SQRT(1)) -> 9558.8106 | P7: =E$504*EXP((K$1-K$2/2)*(1)+K$3*_xlfn.NORM.S.INV(RAND())*SQRT(1)) -> 6249.731 | Q7: =F$504*EXP((L$1-L$2/2)*(1)+L$3*_xlfn.NORM.S.INV(RAND())*SQRT(1)) -> 111.95038 | T7: =N7/C$504*T$2+O7/D$504*U$2+P7/E$504*V$2+Q7/F$504*W$2 -> 9969324.5 | V7: =T7-X$2 -> -30675.457 | X7: -186521.99 | Z7: VaR99%, 1 día = | AA7: =ABS(X9) -> 183105.05 | AB7: =AA7/X$2 -> 0.018310505
A8: 4 | B8: 38940 | C8: 11088.02 | D8: 11040.73 | E8: 6364.7645 | F8: 134.10028 | I8: =LN(C8/C7) -> -0.003272951 | J8: =LN(D8/D7) -> 0.0021780943 | K8: =LN(E8/E7) -> 0.0011442175 | L8: =LN(F8/F7) -> -0.0099267272 | N8: =C$504*EXP((I$1-I$2/2)*(1)+I$3*_xlfn.NORM.S.INV(RAND())*SQRT(1)) -> 11082.272 | O8: =D$504*EXP((J$1-J$2/2)*(1)+J$3*_xlfn.NORM.S.INV(RAND())*SQRT(1)) -> 9463.7895 | P8: =E$504*EXP((K$1-K$2/2)*(1)+K$3*_xlfn.NORM.S.INV(RAND())*SQRT(1)) -> 6127.0153 | Q8: =F$504*EXP((L$1-L$2/2)*(1)+L$3*_xlfn.NORM.S.INV(RAND())*SQRT(1)) -> 111.75953 | T8: =N8/C$504*T$2+O8/D$504*U$2+P8/E$504*V$2+Q8/F$504*W$2 -> 9948645.3 | V8: =T8-X$2 -> -51354.661 | X8: -183553.84 | Z8: CVaR99%, 1 día = | AA8: =ABS(AVERAGE(X5:X8)) -> 204260.45 | AB8: =AA8/X$2 -> 0.020426045
A9: 5 | B9: 38943 | C9: 11097.87 | D9: 11109.504 | E9: 6431.6682 | F9: 136.17097 | I9: =LN(C9/C8) -> 0.00088795182 | J9: =LN(D9/D8) -> 0.0062098298 | K9: =LN(E9/E8) -> 0.010456712 | L9: =LN(F9/F8) -> 0.015323352 | N9: =C$504*EXP((I$1-I$2/2)*(1)+I$3*_xlfn.NORM.S.INV(RAND())*SQRT(1)) -> 11107.13 | O9: =D$504*EXP((J$1-J$2/2)*(1)+J$3*_xlfn.NORM.S.INV(RAND())*SQRT(1)) -> 9532.9762 | P9: =E$504*EXP((K$1-K$2/2)*(1)+K$3*_xlfn.NORM.S.INV(RAND())*SQRT(1)) -> 6152.4772 | Q9: =F$504*EXP((L$1-L$2/2)*(1)+L$3*_xlfn.NORM.S.INV(RAND())*SQRT(1)) -> 113.73718 | T9: =N9/C$504*T$2+O9/D$504*U$2+P9/E$504*V$2+Q9/F$504*W$2 -> 10018452 | V9: =T9-X$2 -> 18452.154 | X9: -183105.05
A10: 6 | B10: 38944 | C10: 11230.26 | D10: 11179.469 | E10: 6540.9463 | F10: 136.32296 | I10: =LN(C10/C9) -> 0.011858723 | J10: =LN(D10/D9) -> 0.0062780468 | K10: =LN(E10/E9) -> 0.01684791 | L10: =LN(F10/F9) -> 0.0011155251 | N10: =C$504*EXP((I$1-I$2/2)*(1)+I$3*_xlfn.NORM.S.INV(RAND())*SQRT(1)) -> 11040.361 | O10: =D$504*EXP((J$1-J$2/2)*(1)+J$3*_xlfn.NORM.S.INV(RAND())*SQRT(1)) -> 9554.4556 | P10: =E$504*EXP((K$1-K$2/2)*(1)+K$3*_xlfn.NORM.S.INV(RAND())*SQRT(1)) -> 6170.1629 | Q10: =F$504*EXP((L$1-L$2/2)*(1)+L$3*_xlfn.NORM.S.INV(RAND())*SQRT(1)) -> 113.86804 | T10: =N10/C$504*T$2+O10/D$504*U$2+P10/E$504*V$2+Q10/F$504*W$2 -> 10006105 | V10: =T10-X$2 -> 6105.4814 | X10: -174428.88 | Z10: VaR99%, 10 días = | AA10: =AA7*SQRT(10) -> 579029 | AB10: =AA10/X$2 -> 0.0579029
A11: 7 | B11: 38945 | C11: 11327.12 | D11: 11203.54 | E11: 6603.2262 | F11: 138.80947 | I11: =LN(C11/C10) -> 0.0085879296 | J11: =LN(D11/D10) -> 0.0021507885 | K11: =LN(E11/E10) -> 0.0094765031 | L11: =LN(F11/F10) -> 0.018075458 | N11: =C$504*EXP((I$1-I$2/2)*(1)+I$3*_xlfn.NORM.S.INV(RAND())*SQRT(1)) -> 11277.233 | O11: =D$504*EXP((J$1-J$2/2)*(1)+J$3*_xlfn.NORM.S.INV(RAND())*SQRT(1)) -> 9540.9111 | P11: =E$504*EXP((K$1-K$2/2)*(1)+K$3*_xlfn.NORM.S.INV(RAND())*SQRT(1)) -> 6184.9449 | Q11: =F$504*EXP((L$1-L$2/2)*(1)+L$3*_xlfn.NORM.S.INV(RAND())*SQRT(1)) -> 112.77744 | T11: =N11/C$504*T$2+O11/D$504*U$2+P11/E$504*V$2+Q11/F$504*W$2 -> 10070887 | V11: =T11-X$2 -> 70886.556 | X11: -169004.58 | Z11: CapitalRiesgo de mercado = | AA11: =3*AA10 -> 1737087 | AB11: =AA11/X$2 -> 0.1737087
A12: 8 | B12: 38946 | C12: 11334.96 | D12: 11170.047 | E12: 6617.1576 | F12: 138.67255 | I12: =LN(C12/C11) -> 0.00069190474 | J12: =LN(D12/D11) -> -0.0029939575 | K12: =LN(E12/E11) -> 0.0021075546 | L12: =LN(F12/F11) -> -0.00098682903 | N12: =C$504*EXP((I$1-I$2/2)*(1)+I$3*_xlfn.NORM.S.INV(RAND())*SQRT(1)) -> 11100.802 | O12: =D$504*EXP((J$1-J$2/2)*(1)+J$3*_xlfn.NORM.S.INV(RAND())*SQRT(1)) -> 9698.995 | P12: =E$504*EXP((K$1-K$2/2)*(1)+K$3*_xlfn.NORM.S.INV(RAND())*SQRT(1)) -> 6220.678 | Q12: =F$504*EXP((L$1-L$2/2)*(1)+L$3*_xlfn.NORM.S.INV(RAND())*SQRT(1)) -> 113.64476 | T12: =N12/C$504*T$2+O12/D$504*U$2+P12/E$504*V$2+Q12/F$504*W$2 -> 10077398 | V12: =T12-X$2 -> 77398.133 | X12: -164060.83 | Z12: Ojo: solo faltaría la ponderación por calidad crediticia de los activos en los que se invierten.
A13: 9 | B13: 38947 | C13: 11381.47 | D13: 11096.031 | E13: 6584.2179 | F13: 139.15656 | I13: =LN(C13/C12) -> 0.0040948393 | J13: =LN(D13/D12) -> -0.0066483979 | K13: =LN(E13/E12) -> -0.00499034 | L13: =LN(F13/F12) -> 0.0034841972 | N13: =C$504*EXP((I$1-I$2/2)*(1)+I$3*_xlfn.NORM.S.INV(RAND())*SQRT(1)) -> 10938.395 | O13: =D$504*EXP((J$1-J$2/2)*(1)+J$3*_xlfn.NORM.S.INV(RAND())*SQRT(1)) -> 9682.2461 | P13: =E$504*EXP((K$1-K$2/2)*(1)+K$3*_xlfn.NORM.S.INV(RAND())*SQRT(1)) -> 6170.1964 | Q13: =F$504*EXP((L$1-L$2/2)*(1)+L$3*_xlfn.NORM.S.INV(RAND())*SQRT(1)) -> 110.47476 | T13: =N13/C$504*T$2+O13/D$504*U$2+P13/E$504*V$2+Q13/F$504*W$2 -> 9948888.9 | V13: =T13-X$2 -> -51111.099 | X13: -148452.99
A14: 10 | B14: 38950 | C14: 11345.04 | D14: 11221.134 | E14: 6594.3031 | F14: 137.83049 | I14: =LN(C14/C13) -> -0.0032059503 | J14: =LN(D14/D13) -> 0.011211556 | K14: =LN(E14/E13) -> 0.0015305382 | L14: =LN(F14/F13) -> -0.0095750534 | N14: =C$504*EXP((I$1-I$2/2)*(1)+I$3*_xlfn.NORM.S.INV(RAND())*SQRT(1)) -> 10909.211 | O14: =D$504*EXP((J$1-J$2/2)*(1)+J$3*_xlfn.NORM.S.INV(RAND())*SQRT(1)) -> 9857.1744 | P14: =E$504*EXP((K$1-K$2/2)*(1)+K$3*_xlfn.NORM.S.INV(RAND())*SQRT(1)) -> 6257.091 | Q14: =F$504*EXP((L$1-L$2/2)*(1)+L$3*_xlfn.NORM.S.INV(RAND())*SQRT(1)) -> 114.37291 | T14: =N14/C$504*T$2+O14/D$504*U$2+P14/E$504*V$2+Q14/F$504*W$2 -> 10076080 | V14: =T14-X$2 -> 76080.371 | X14: -142581.74 | Z14: Yo | AA14: =AB7 -> 0.018310505
A15: 11 | B15: 38951 | C15: 11339.84 | D15: 11147.06 | E15: 6571.4121 | F15: 138.94187 | I15: =LN(C15/C14) -> -0.00045845516 | J15: =LN(D15/D14) -> -0.0066232052 | K15: =LN(E15/E14) -> -0.0034773634 | L15: =LN(F15/F14) -> 0.0080310721 | N15: =C$504*EXP((I$1-I$2/2)*(1)+I$3*_xlfn.NORM.S.INV(RAND())*SQRT(1)) -> 10726.006 | O15: =D$504*EXP((J$1-J$2/2)*(1)+J$3*_xlfn.NORM.S.INV(RAND())*SQRT(1)) -> 9529.9174 | P15: =E$504*EXP((K$1-K$2/2)*(1)+K$3*_xlfn.NORM.S.INV(RAND())*SQRT(1)) -> 6305.2568 | Q15: =F$504*EXP((L$1-L$2/2)*(1)+L$3*_xlfn.NORM.S.INV(RAND())*SQRT(1)) -> 109.67742 | T15: =N15/C$504*T$2+O15/D$504*U$2+P15/E$504*V$2+Q15/F$504*W$2 -> 9831855.9 | V15: =T15-X$2 -> -168144.09 | X15: -142087.73 | Z15: Ochoa | AA15: 0.0174
A16: 12 | B16: 38952 | C16: 11297.9 | D16: 11097.082 | E16: 6502.9811 | F16: 138.70274 | I16: =LN(C16/C15) -> -0.0037053211 | J16: =LN(D16/D15) -> -0.0044936041 | K16: =LN(E16/E15) -> -0.010468043 | L16: =LN(F16/F15) -> -0.0017225692 | N16: =C$504*EXP((I$1-I$2/2)*(1)+I$3*_xlfn.NORM.S.INV(RAND())*SQRT(1)) -> 11202.034 | O16: =D$504*EXP((J$1-J$2/2)*(1)+J$3*_xlfn.NORM.S.INV(RAND())*SQRT(1)) -> 9531.3198 | P16: =E$504*EXP((K$1-K$2/2)*(1)+K$3*_xlfn.NORM.S.INV(RAND())*SQRT(1)) -> 6302.055 | Q16: =F$504*EXP((L$1-L$2/2)*(1)+L$3*_xlfn.NORM.S.INV(RAND())*SQRT(1)) -> 115.11431 | T16: =N16/C$504*T$2+O16/D$504*U$2+P16/E$504*V$2+Q16/F$504*W$2 -> 10100912 | V16: =T16-X$2 -> 100912.36 | X16: -138728.56 | Z16: Jimenez | AA16: 0.0157
A17: 13 | B17: 38953 | C17: 11304.46 | D17: 11100.816 | E17: 6541.5174 | F17: 137.21303 | I17: =LN(C17/C16) -> 0.00058047037 | J17: =LN(D17/D16) -> 0.00033640483 | K17: =LN(E17/E16) -> 0.0059084599 | L17: =LN(F17/F16) -> -0.01079836 | N17: =C$504*EXP((I$1-I$2/2)*(1)+I$3*_xlfn.NORM.S.INV(RAND())*SQRT(1)) -> 11101.689 | O17: =D$504*EXP((J$1-J$2/2)*(1)+J$3*_xlfn.NORM.S.INV(RAND())*SQRT(1)) -> 9794.5597 | P17: =E$504*EXP((K$1-K$2/2)*(1)+K$3*_xlfn.NORM.S.INV(RAND())*SQRT(1)) -> 6129.0406 | Q17: =F$504*EXP((L$1-L$2/2)*(1)+L$3*_xlfn.NORM.S.INV(RAND())*SQRT(1)) -> 112.54716 | T17: =N17/C$504*T$2+O17/D$504*U$2+P17/E$504*V$2+Q17/F$504*W$2 -> 10073348 | V17: =T17-X$2 -> 73348.092 | X17: -138003.61 | Z17: Rafa | AA17: 0.0163
A18: 14 | B18: 38954 | C18: 11284.05 | D18: 11088.215 | E18: 6515.1434 | F18: 135.87945 | I18: =LN(C18/C17) -> -0.0018071139 | J18: =LN(D18/D17) -> -0.0011357343 | K18: =LN(E18/E17) -> -0.0040399353 | L18: =LN(F18/F17) -> -0.0097665757 | N18: =C$504*EXP((I$1-I$2/2)*(1)+I$3*_xlfn.NORM.S.INV(RAND())*SQRT(1)) -> 11315.275 | O18: =D$504*EXP((J$1-J$2/2)*(1)+J$3*_xlfn.NORM.S.INV(RAND())*SQRT(1)) -> 9442.5452 | P18: =E$504*EXP((K$1-K$2/2)*(1)+K$3*_xlfn.NORM.S.INV(RAND())*SQRT(1)) -> 6167.0754 | Q18: =F$504*EXP((L$1-L$2/2)*(1)+L$3*_xlfn.NORM.S.INV(RAND())*SQRT(1)) -> 112.10248 | T18: =N18/C$504*T$2+O18/D$504*U$2+P18/E$504*V$2+Q18/F$504*W$2 -> 10039106 | V18: =T18-X$2 -> 39105.824 | X18: -129465.42 | Z18: Palomares | AA18: 0.0143
A19: 15 | B19: 38958 | C19: 11369.94 | D19: 11145.963 | E19: 6583.7203 | F19: 135.90968 | I19: =LN(C19/C18) -> 0.0075828065 | J19: =LN(D19/D18) -> 0.0051945144 | K19: =LN(E19/E18) -> 0.010470765 | L19: =LN(F19/F18) -> 0.00022243305 | N19: =C$504*EXP((I$1-I$2/2)*(1)+I$3*_xlfn.NORM.S.INV(RAND())*SQRT(1)) -> 11192.835 | O19: =D$504*EXP((J$1-J$2/2)*(1)+J$3*_xlfn.NORM.S.INV(RAND())*SQRT(1)) -> 9489.9863 | P19: =E$504*EXP((K$1-K$2/2)*(1)+K$3*_xlfn.NORM.S.INV(RAND())*SQRT(1)) -> 6271.3277 | Q19: =F$504*EXP((L$1-L$2/2)*(1)+L$3*_xlfn.NORM.S.INV(RAND())*SQRT(1)) -> 111.12364 | T19: =N19/C$504*T$2+O19/D$504*U$2+P19/E$504*V$2+Q19/F$504*W$2 -> 10008959 | V19: =T19-X$2 -> 8958.7816 | X19: -128881.86
A20: 16 | B20: 38959 | C20: 11382.91 | D20: 11300.653 | E20: 6651.4245 | F20: 135.60034 | I20: =LN(C20/C19) -> 0.0011400771 | J20: =LN(D20/D19) -> 0.013783124 | K20: =LN(E20/E19) -> 0.010231062 | L20: =LN(F20/F19) -> -0.0022786653 | N20: =C$504*EXP((I$1-I$2/2)*(1)+I$3*_xlfn.NORM.S.INV(RAND())*SQRT(1)) -> 10967.941 | O20: =D$504*EXP((J$1-J$2/2)*(1)+J$3*_xlfn.NORM.S.INV(RAND())*SQRT(1)) -> 9655.761 | P20: =E$504*EXP((K$1-K$2/2)*(1)+K$3*_xlfn.NORM.S.INV(RAND())*SQRT(1)) -> 6169.1907 | Q20: =F$504*EXP((L$1-L$2/2)*(1)+L$3*_xlfn.NORM.S.INV(RAND())*SQRT(1)) -> 110.30966 | T20: =N20/C$504*T$2+O20/D$504*U$2+P20/E$504*V$2+Q20/F$504*W$2 -> 9948245.5 | V20: =T20-X$2 -> -51754.469 | X20: -127246.21 | AA20: =AVERAGE(AA14:AA18) -> 0.016402101
A21: 17 | B21: 38960 | C21: 11381.15 | D21: 11232.221 | E21: 6610.8281 | F21: 137.60239 | I21: =LN(C21/C20) -> -0.00015462971 | J21: =LN(D21/D20) -> -0.0060739789 | K21: =LN(E21/E20) -> -0.006122121 | L21: =LN(F21/F20) -> 0.014656377 | N21: =C$504*EXP((I$1-I$2/2)*(1)+I$3*_xlfn.NORM.S.INV(RAND())*SQRT(1)) -> 11194.449 | O21: =D$504*EXP((J$1-J$2/2)*(1)+J$3*_xlfn.NORM.S.INV(RAND())*SQRT(1)) -> 9855.208 | P21: =E$504*EXP((K$1-K$2/2)*(1)+K$3*_xlfn.NORM.S.INV(RAND())*SQRT(1)) -> 6355.3779 | Q21: =F$504*EXP((L$1-L$2/2)*(1)+L$3*_xlfn.NORM.S.INV(RAND())*SQRT(1)) -> 115.99525 | T21: =N21/C$504*T$2+O21/D$504*U$2+P21/E$504*V$2+Q21/F$504*W$2 -> 10223592 | V21: =T21-X$2 -> 223592.13 | X21: -126675.85
A22: 18 | B22: 38961 | C22: 11464.15 | D22: 11323.517 | E22: 6636.9398 | F22: 137.52344 | I22: =LN(C22/C21) -> 0.0072662968 | J22: =LN(D22/D21) -> 0.008095187 | K22: =LN(E22/E21) -> 0.0039420599 | L22: =LN(F22/F21) -> -0.00057389654 | N22: =C$504*EXP((I$1-I$2/2)*(1)+I$3*_xlfn.NORM.S.INV(RAND())*SQRT(1)) -> 10992.799 | O22: =D$504*EXP((J$1-J$2/2)*(1)+J$3*_xlfn.NORM.S.INV(RAND())*SQRT(1)) -> 9697.382 | P22: =E$504*EXP((K$1-K$2/2)*(1)+K$3*_xlfn.NORM.S.INV(RAND())*SQRT(1)) -> 6050.1655 | Q22: =F$504*EXP((L$1-L$2/2)*(1)+L$3*_xlfn.NORM.S.INV(RAND())*SQRT(1)) -> 112.99909 | T22: =N22/C$504*T$2+O22/D$504*U$2+P22/E$504*V$2+Q22/F$504*W$2 -> 9998752.9 | V22: =T22-X$2 -> -1247.0943 | X22: -121083.5
A23: 19 | B23: 38965 | C23: 11469.28 | D23: 11320.965 | E23: 6625.064 | F23: 141.13661 | I23: =LN(C23/C22) -> 0.00044738184 | J23: =LN(D23/D22) -> -0.00022535468 | K23: =LN(E23/E22) -> -0.0017909491 | L23: =LN(F23/F22) -> 0.025933884 | N23: =C$504*EXP((I$1-I$2/2)*(1)+I$3*_xlfn.NORM.S.INV(RAND())*SQRT(1)) -> 11149.258 | O23: =D$504*EXP((J$1-J$2/2)*(1)+J$3*_xlfn.NORM.S.INV(RAND())*SQRT(1)) -> 9785.9757 | P23: =E$504*EXP((K$1-K$2/2)*(1)+K$3*_xlfn.NORM.S.INV(RAND())*SQRT(1)) -> 6160.5198 | Q23: =F$504*EXP((L$1-L$2/2)*(1)+L$3*_xlfn.NORM.S.INV(RAND())*SQRT(1)) -> 112.99971 | T23: =N23/C$504*T$2+O23/D$504*U$2+P23/E$504*V$2+Q23/F$504*W$2 -> 10101028 | V23: =T23-X$2 -> 101027.96 | X23: -119072.52
A24: 20 | B24: 38966 | C24: 11406.2 | D24: 11150.642 | E24: 6541.5857 | F24: 139.6218 | I24: =LN(C24/C23) -> -0.0055150895 | J24: =LN(D24/D23) -> -0.015159317 | K24: =LN(E24/E23) -> -0.012680443 | L24: =LN(F24/F23) -> -0.010790955 | N24: =C$504*EXP((I$1-I$2/2)*(1)+I$3*_xlfn.NORM.S.INV(RAND())*SQRT(1)) -> 11109.835 | O24: =D$504*EXP((J$1-J$2/2)*(1)+J$3*_xlfn.NORM.S.INV(RAND())*SQRT(1)) -> 9367.5157 | P24: =E$504*EXP((K$1-K$2/2)*(1)+K$3*_xlfn.NORM.S.INV(RAND())*SQRT(1)) -> 6137.5756 | Q24: =F$504*EXP((L$1-L$2/2)*(1)+L$3*_xlfn.NORM.S.INV(RAND())*SQRT(1)) -> 114.68194 | T24: =N24/C$504*T$2+O24/D$504*U$2+P24/E$504*V$2+Q24/F$504*W$2 -> 9982071.4 | V24: =T24-X$2 -> -17928.567 | X24: -119011.54
A25: 21 | B25: 38967 | C25: 11331.44 | D25: 10978.079 | E25: 6442.6916 | F25: 137.50459 | I25: =LN(C25/C24) -> -0.006575904 | J25: =LN(D25/D24) -> -0.015596534 | K25: =LN(E25/E24) -> -0.015233188 | L25: =LN(F25/F24) -> -0.015279977 | N25: =C$504*EXP((I$1-I$2/2)*(1)+I$3*_xlfn.NORM.S.INV(RAND())*SQRT(1)) -> 11006.485 | O25: =D$504*EXP((J$1-J$2/2)*(1)+J$3*_xlfn.NORM.S.INV(RAND())*SQRT(1)) -> 9446.8397 | P25: =E$504*EXP((K$1-K$2/2)*(1)+K$3*_xlfn.NORM.S.INV(RAND())*SQRT(1)) -> 6268.5251 | Q25: =F$504*EXP((L$1-L$2/2)*(1)+L$3*_xlfn.NORM.S.INV(RAND())*SQRT(1)) -> 113.82001 | T25: =N25/C$504*T$2+O25/D$504*U$2+P25/E$504*V$2+Q25/F$504*W$2 -> 9975194 | V25: =T25-X$2 -> -24805.993 | X25: -116167.87
A26: 22 | B26: 38968 | C26: 11392.11 | D26: 10965.482 | E26: 6427.9361 | F26: 137.74593 | I26: =LN(C26/C25) -> 0.0053398474 | J26: =LN(D26/D25) -> -0.0011481246 | K26: =LN(E26/E25) -> -0.0022928924 | L26: =LN(F26/F25) -> 0.0017535803 | N26: =C$504*EXP((I$1-I$2/2)*(1)+I$3*_xlfn.NORM.S.INV(RAND())*SQRT(1)) -> 11161.727 | O26: =D$504*EXP((J$1-J$2/2)*(1)+J$3*_xlfn.NORM.S.INV(RAND())*SQRT(1)) -> 9575.6667 | P26: =E$504*EXP((K$1-K$2/2)*(1)+K$3*_xlfn.NORM.S.INV(RAND())*SQRT(1)) -> 6108.3479 | Q26: =F$504*EXP((L$1-L$2/2)*(1)+L$3*_xlfn.NORM.S.INV(RAND())*SQRT(1)) -> 116.46109 | T26: =N26/C$504*T$2+O26/D$504*U$2+P26/E$504*V$2+Q26/F$504*W$2 -> 10092777 | V26: =T26-X$2 -> 92776.621 | X26: -114657.02
A27: 23 | B27: 38971 | C27: 11396.84 | D27: 10897.115 | E27: 6419.9898 | F27: 134.14625 | I27: =LN(C27/C26) -> 0.00041511347 | J27: =LN(D27/D26) -> -0.0062543029 | K27: =LN(E27/E26) -> -0.0012369779 | L27: =LN(F27/F26) -> -0.026480254 | N27: =C$504*EXP((I$1-I$2/2)*(1)+I$3*_xlfn.NORM.S.INV(RAND())*SQRT(1)) -> 11103.178 | O27: =D$504*EXP((J$1-J$2/2)*(1)+J$3*_xlfn.NORM.S.INV(RAND())*SQRT(1)) -> 9788.5011 | P27: =E$504*EXP((K$1-K$2/2)*(1)+K$3*_xlfn.NORM.S.INV(RAND())*SQRT(1)) -> 6265.4568 | Q27: =F$504*EXP((L$1-L$2/2)*(1)+L$3*_xlfn.NORM.S.INV(RAND())*SQRT(1)) -> 110.39656 | T27: =N27/C$504*T$2+O27/D$504*U$2+P27/E$504*V$2+Q27/F$504*W$2 -> 10055872 | V27: =T27-X$2 -> 55872.482 | X27: -114186.39
A28: 24 | B28: 38972 | C28: 11498.09 | D28: 11057.6 | E28: 6504.2127 | F28: 133.47491 | I28: =LN(C28/C27) -> 0.0088448106 | J28: =LN(D28/D27) -> 0.014619881 | K28: =LN(E28/E27) -> 0.013033533 | L28: =LN(F28/F27) -> -0.0050171454 | N28: =C$504*EXP((I$1-I$2/2)*(1)+I$3*_xlfn.NORM.S.INV(RAND())*SQRT(1)) -> 10850.49 | O28: =D$504*EXP((J$1-J$2/2)*(1)+J$3*_xlfn.NORM.S.INV(RAND())*SQRT(1)) -> 9489.8189 | P28: =E$504*EXP((K$1-K$2/2)*(1)+K$3*_xlfn.NORM.S.INV(RAND())*SQRT(1)) -> 6205.5213 | Q28: =F$504*EXP((L$1-L$2/2)*(1)+L$3*_xlfn.NORM.S.INV(RAND())*SQRT(1)) -> 113.28001 | T28: =N28/C$504*T$2+O28/D$504*U$2+P28/E$504*V$2+Q28/F$504*W$2 -> 9912279.2 | V28: =T28-X$2 -> -87720.802 | X28: -112700.39
A29: 25 | B29: 38973 | C29: 11543.32 | D29: 11045.518 | E29: 6513.6029 | F29: 133.84932 | I29: =LN(C29/C28) -> 0.0039259801 | J29: =LN(D29/D28) -> -0.0010932106 | K29: =LN(E29/E28) -> 0.0014426813 | L29: =LN(F29/F28) -> 0.0028012119 | N29: =C$504*EXP((I$1-I$2/2)*(1)+I$3*_xlfn.NORM.S.INV(RAND())*SQRT(1)) -> 11215.886 | O29: =D$504*EXP((J$1-J$2/2)*(1)+J$3*_xlfn.NORM.S.INV(RAND())*SQRT(1)) -> 9639.8458 | P29: =E$504*EXP((K$1-K$2/2)*(1)+K$3*_xlfn.NORM.S.INV(RAND())*SQRT(1)) -> 6203.2695 | Q29: =F$504*EXP((L$1-L$2/2)*(1)+L$3*_xlfn.NORM.S.INV(RAND())*SQRT(1)) -> 113.46807 | T29: =N29/C$504*T$2+O29/D$504*U$2+P29/E$504*V$2+Q29/F$504*W$2 -> 10094739 | V29: =T29-X$2 -> 94739.113 | X29: -111994.03
A30: 26 | B30: 38974 | C30: 11527.39 | D30: 11112.022 | E30: 6533.0231 | F30: 135.78392 | I30: =LN(C30/C29) -> -0.001380972 | J30: =LN(D30/D29) -> 0.0060028432 | K30: =LN(E30/E29) -> 0.0029770381 | L30: =LN(F30/F29) -> 0.014350073 | N30: =C$504*EXP((I$1-I$2/2)*(1)+I$3*_xlfn.NORM.S.INV(RAND())*SQRT(1)) -> 11248.947 | O30: =D$504*EXP((J$1-J$2/2)*(1)+J$3*_xlfn.NORM.S.INV(RAND())*SQRT(1)) -> 9497.4246 | P30: =E$504*EXP((K$1-K$2/2)*(1)+K$3*_xlfn.NORM.S.INV(RAND())*SQRT(1)) -> 6317.114 | Q30: =F$504*EXP((L$1-L$2/2)*(1)+L$3*_xlfn.NORM.S.INV(RAND())*SQRT(1)) -> 111.4921 | T30: =N30/C$504*T$2+O30/D$504*U$2+P30/E$504*V$2+Q30/F$504*W$2 -> 10045563 | V30: =T30-X$2 -> 45562.767 | X30: -110721.09
A31: 27 | B31: 38975 | C31: 11560.77 | D31: 11037.006 | E31: 6508.3871 | F31: 134.93435 | I31: =LN(C31/C30) -> 0.0028915274 | J31: =LN(D31/D30) -> -0.0067737805 | K31: =LN(E31/E30) -> -0.0037781206 | L31: =LN(F31/F30) -> -0.0062764455 | N31: =C$504*EXP((I$1-I$2/2)*(1)+I$3*_xlfn.NORM.S.INV(RAND())*SQRT(1)) -> 10897.699 | O31: =D$504*EXP((J$1-J$2/2)*(1)+J$3*_xlfn.NORM.S.INV(RAND())*SQRT(1)) -> 9420.4648 | P31: =E$504*EXP((K$1-K$2/2)*(1)+K$3*_xlfn.NORM.S.INV(RAND())*SQRT(1)) -> 6272.7878 | Q31: =F$504*EXP((L$1-L$2/2)*(1)+L$3*_xlfn.NORM.S.INV(RAND())*SQRT(1)) -> 112.87039 | T31: =N31/C$504*T$2+O31/D$504*U$2+P31/E$504*V$2+Q31/F$504*W$2 -> 9911325.8 | V31: =T31-X$2 -> -88674.153 | X31: -109779.3
A32: 28 | B32: 38979 | C32: 11540.91 | D32: 11003.44 | E32: 6498.971 | F32: 135.46919 | I32: =LN(C32/C31) -> -0.0017193559 | J32: =LN(D32/D31) -> -0.0030458354 | K32: =LN(E32/E31) -> -0.0014478054 | L32: =LN(F32/F31) -> 0.0039559041 | N32: =C$504*EXP((I$1-I$2/2)*(1)+I$3*_xlfn.NORM.S.INV(RAND())*SQRT(1)) -> 11063.781 | O32: =D$504*EXP((J$1-J$2/2)*(1)+J$3*_xlfn.NORM.S.INV(RAND())*SQRT(1)) -> 9853.9713 | P32: =E$504*EXP((K$1-K$2/2)*(1)+K$3*_xlfn.NORM.S.INV(RAND())*SQRT(1)) -> 6017.3168 | Q32: =F$504*EXP((L$1-L$2/2)*(1)+L$3*_xlfn.NORM.S.INV(RAND())*SQRT(1)) -> 113.25958 | T32: =N32/C$504*T$2+O32/D$504*U$2+P32/E$504*V$2+Q32/F$504*W$2 -> 10072767 | V32: =T32-X$2 -> 72767.465 | X32: -109223.09
... A504: 500 | B504: 39716 | C504: 11022.06 | D504: 9599.8984 | E504: 6200.3961 | F504: 112.82212 | I504: =LN(C504/C503) -> 0.018024741 | J504: =LN(D504/D503) -> 0.016946983 | K504: =LN(E504/E503) -> 0.027213871 | L504: =LN(F504/F503) -> -0.012667618 | N504: =C$504*EXP((I$1-I$2/2)*(1)+I$3*_xlfn.NORM.S.INV(RAND())*SQRT(1)) -> 10922.931 | O504: =D$504*EXP((J$1-J$2/2)*(1)+J$3*_xlfn.NORM.S.INV(RAND())*SQRT(1)) -> 9484.0695 | P504: =E$504*EXP((K$1-K$2/2)*(1)+K$3*_xlfn.NORM.S.INV(RAND())*SQRT(1)) -> 6258.417 | Q504: =F$504*EXP((L$1-L$2/2)*(1)+L$3*_xlfn.NORM.S.INV(RAND())*SQRT(1)) -> 113.66556 | T504: =N504/C$504*T$2+O504/D$504*U$2+P504/E$504*V$2+Q504/F$504*W$2 -> 9952137.5 | V504: =T504-X$2 -> -47862.529 | X504: 203039.06

Sheet Simulación ST
D1: Adjusted | E1: Adjusted | F1: Adjusted | G1: Portfolio | H1: DJIA | I1: FTSE 100 | J1: CAC40 | K1: Nikkei 225
A2: Consecutivo | B2: Fecha | C2: DJIA | D2: FTSE-500 | E2: CAC-40 | F2: Nikkei | G2: Investments | H2: 4000000 | I2: 3000000 | J2: 1000000 | K2: 2000000 | L2: =SUM(H2:K2) -> 10000000
A3: 0 | B3: 38936 | C3: 11219.38 | D3: 11131.842 | E3: 6373.894 | F3: 131.77443 | G3: =C3/$C$503*H$2+D3/$D$503*I$2+E3/$E$503*J$2+F3/$F$503*K$2 -> 10914296
A4: 1 | B4: 38937 | C4: 11173.59 | D4: 11096.28 | E4: 6378.1615 | F4: 134.38182 | G4: =C4/$C$503*H$2+D4/$D$503*I$2+E4/$E$503*J$2+F4/$F$503*K$2 -> 10933475
A5: 2 | B5: 38938 | C5: 11076.18 | D5: 11185.35 | E5: 6474.0402 | F5: 135.9433 | G5: =C5/$C$503*H$2+D5/$D$503*I$2+E5/$E$503*J$2+F5/$F$503*K$2 -> 10969103
A6: 3 | B6: 38939 | C6: 11124.37 | D6: 11016.708 | E6: 6357.4859 | F6: 135.43809 | G6: =C6/$C$503*H$2+D6/$D$503*I$2+E6/$E$503*J$2+F6/$F$503*K$2 -> 10906136
A7: 4 | B7: 38940 | C7: 11088.02 | D7: 11040.73 | E7: 6364.7645 | F7: 134.10028 | G7: =C7/$C$503*H$2+D7/$D$503*I$2+E7/$E$503*J$2+F7/$F$503*K$2 -> 10877910
A8: 5 | B8: 38943 | C8: 11097.87 | D8: 11109.504 | E8: 6431.6682 | F8: 136.17097 | G8: =C8/$C$503*H$2+D8/$D$503*I$2+E8/$E$503*J$2+F8/$F$503*K$2 -> 10950474
A9: 6 | B9: 38944 | C9: 11230.26 | D9: 11179.469 | E9: 6540.9463 | F9: 136.32296 | G9: =C9/$C$503*H$2+D9/$D$503*I$2+E9/$E$503*J$2+F9/$F$503*K$2 -> 11040703
A10: 7 | B10: 38945 | C10: 11327.12 | D10: 11203.54 | E10: 6603.2262 | F10: 138.80947 | G10: =C10/$C$503*H$2+D10/$D$503*I$2+E10/$E$503*J$2+F10/$F$503*K$2 -> 11137499
A11: 8 | B11: 38946 | C11: 11334.96 | D11: 11170.047 | E11: 6617.1576 | F11: 138.67255 | G11: =C11/$C$503*H$2+D11/$D$503*I$2+E11/$E$503*J$2+F11/$F$503*K$2 -> 11129697
A12: 9 | B12: 38947 | C12: 11381.47 | D12: 11096.031 | E12: 6584.2179 | F12: 139.15656 | G12: =C12/$C$503*H$2+D12/$D$503*I$2+E12/$E$503*J$2+F12/$F$503*K$2 -> 11126713
A13: 10 | B13: 38950 | C13: 11345.04 | D13: 11221.134 | E13: 6594.3031 | F13: 137.83049 | G13: =C13/$C$503*H$2+D13/$D$503*I$2+E13/$E$503*J$2+F13/$F$503*K$2 -> 11130707
A14: 11 | B14: 38951 | C14: 11339.84 | D14: 11147.06 | E14: 6571.4121 | F14: 138.94187 | G14: =C14/$C$503*H$2+D14/$D$503*I$2+E14/$E$503*J$2+F14/$F$503*K$2 -> 11121681
... A503: 500 | B503: 39716 | C503: 11022.06 | D503: 9599.8984 | E503: 6200.3961 | F503: 112.82212 | G503: =C503/$C$503*H$2+D503/$D$503*I$2+E503/$E$503*J$2+F503/$F$503*K$2 -> 10000000
A504: 501 | B504: 39717 | C504: =C503*EXP(('VaR 2 Sim MC'!I$1-'VaR 2 Sim MC'!I$2/2)*1+'VaR 2 Sim MC'!I$3*_xlfn.NORM.S.INV(RAND())*SQRT(1)) -> 11071.988 | D504: =D503*EXP(('VaR 2 Sim MC'!J$1-'VaR 2 Sim MC'!J$2/2)*1+'VaR 2 Sim MC'!J$3*_xlfn.NORM.S.INV(RAND())*SQRT(1)) -> 9325.8879 | E504: =E503*EXP(('VaR 2 Sim MC'!K$1-'VaR 2 Sim MC'!K$2/2)*1+'VaR 2 Sim MC'!K$3*_xlfn.NORM.S.INV(RAND())*SQRT(1)) -> 6216.0064 | F504: =F503*EXP(('VaR 2 Sim MC'!L$1-'VaR 2 Sim MC'!L$2/2)*1+'VaR 2 Sim MC'!L$3*_xlfn.NORM.S.INV(RAND())*SQRT(1)) -> 112.82142 | G504: =C504/$C$503*H$2+D504/$D$503*I$2+E504/$E$503*J$2+F504/$F$503*K$2 -> 9934995.4
A505: 502 | B505: 39718 | C505: =C504*EXP(('VaR 2 Sim MC'!I$1-'VaR 2 Sim MC'!I$2/2)*1+'VaR 2 Sim MC'!I$3*_xlfn.NORM.S.INV(RAND())*SQRT(1)) -> 11158.782 | D505: =D504*EXP(('VaR 2 Sim MC'!J$1-'VaR 2 Sim MC'!J$2/2)*1+'VaR 2 Sim MC'!J$3*_xlfn.NORM.S.INV(RAND())*SQRT(1)) -> 9333.1762 | E505: =E504*EXP(('VaR 2 Sim MC'!K$1-'VaR 2 Sim MC'!K$2/2)*1+'VaR 2 Sim MC'!K$3*_xlfn.NORM.S.INV(RAND())*SQRT(1)) -> 6127.5736 | F505: =F504*EXP(('VaR 2 Sim MC'!L$1-'VaR 2 Sim MC'!L$2/2)*1+'VaR 2 Sim MC'!L$3*_xlfn.NORM.S.INV(RAND())*SQRT(1)) -> 112.49965 | G505: =C505/$C$503*H$2+D505/$D$503*I$2+E505/$E$503*J$2+F505/$F$503*K$2 -> 9948804.7
A506: 503 | B506: 39719 | C506: =C505*EXP(('VaR 2 Sim MC'!I$1-'VaR 2 Sim MC'!I$2/2)*1+'VaR 2 Sim MC'!I$3*_xlfn.NORM.S.INV(RAND())*SQRT(1)) -> 11136.628 | D506: =D505*EXP(('VaR 2 Sim MC'!J$1-'VaR 2 Sim MC'!J$2/2)*1+'VaR 2 Sim MC'!J$3*_xlfn.NORM.S.INV(RAND())*SQRT(1)) -> 9370.9611 | E506: =E505*EXP(('VaR 2 Sim MC'!K$1-'VaR 2 Sim MC'!K$2/2)*1+'VaR 2 Sim MC'!K$3*_xlfn.NORM.S.INV(RAND())*SQRT(1)) -> 6144.9263 | F506: =F505*EXP(('VaR 2 Sim MC'!L$1-'VaR 2 Sim MC'!L$2/2)*1+'VaR 2 Sim MC'!L$3*_xlfn.NORM.S.INV(RAND())*SQRT(1)) -> 112.78983 | G506: =C506/$C$503*H$2+D506/$D$503*I$2+E506/$E$503*J$2+F506/$F$503*K$2 -> 9960515.5
A507: 504 | B507: 39720 | C507: =C506*EXP(('VaR 2 Sim MC'!I$1-'VaR 2 Sim MC'!I$2/2)*1+'VaR 2 Sim MC'!I$3*_xlfn.NORM.S.INV(RAND())*SQRT(1)) -> 11008.882 | D507: =D506*EXP(('VaR 2 Sim MC'!J$1-'VaR 2 Sim MC'!J$2/2)*1+'VaR 2 Sim MC'!J$3*_xlfn.NORM.S.INV(RAND())*SQRT(1)) -> 9236.8121 | E507: =E506*EXP(('VaR 2 Sim MC'!K$1-'VaR 2 Sim MC'!K$2/2)*1+'VaR 2 Sim MC'!K$3*_xlfn.NORM.S.INV(RAND())*SQRT(1)) -> 6111.572 | F507: =F506*EXP(('VaR 2 Sim MC'!L$1-'VaR 2 Sim MC'!L$2/2)*1+'VaR 2 Sim MC'!L$3*_xlfn.NORM.S.INV(RAND())*SQRT(1)) -> 112.51279 | G507: =C507/$C$503*H$2+D507/$D$503*I$2+E507/$E$503*J$2+F507/$F$503*K$2 -> 9861942.9
A508: 505 | B508: 39721 | C508: =C507*EXP(('VaR 2 Sim MC'!I$1-'VaR 2 Sim MC'!I$2/2)*1+'VaR 2 Sim MC'!I$3*_xlfn.NORM.S.INV(RAND())*SQRT(1)) -> 11045.813 | D508: =D507*EXP(('VaR 2 Sim MC'!J$1-'VaR 2 Sim MC'!J$2/2)*1+'VaR 2 Sim MC'!J$3*_xlfn.NORM.S.INV(RAND())*SQRT(1)) -> 9017.8045 | E508: =E507*EXP(('VaR 2 Sim MC'!K$1-'VaR 2 Sim MC'!K$2/2)*1+'VaR 2 Sim MC'!K$3*_xlfn.NORM.S.INV(RAND())*SQRT(1)) -> 6146.9315 | F508: =F507*EXP(('VaR 2 Sim MC'!L$1-'VaR 2 Sim MC'!L$2/2)*1+'VaR 2 Sim MC'!L$3*_xlfn.NORM.S.INV(RAND())*SQRT(1)) -> 113.50931 | G508: =C508/$C$503*H$2+D508/$D$503*I$2+E508/$E$503*J$2+F508/$F$503*K$2 -> 9830272.8
A509: 506 | B509: 39722 | C509: =C508*EXP(('VaR 2 Sim MC'!I$1-'VaR 2 Sim MC'!I$2/2)*1+'VaR 2 Sim MC'!I$3*_xlfn.NORM.S.INV(RAND())*SQRT(1)) -> 11083.738 | D509: =D508*EXP(('VaR 2 Sim MC'!J$1-'VaR 2 Sim MC'!J$2/2)*1+'VaR 2 Sim MC'!J$3*_xlfn.NORM.S.INV(RAND())*SQRT(1)) -> 9155.1781 | E509: =E508*EXP(('VaR 2 Sim MC'!K$1-'VaR 2 Sim MC'!K$2/2)*1+'VaR 2 Sim MC'!K$3*_xlfn.NORM.S.INV(RAND())*SQRT(1)) -> 6100.4646 | F509: =F508*EXP(('VaR 2 Sim MC'!L$1-'VaR 2 Sim MC'!L$2/2)*1+'VaR 2 Sim MC'!L$3*_xlfn.NORM.S.INV(RAND())*SQRT(1)) -> 110.88158 | G509: =C509/$C$503*H$2+D509/$D$503*I$2+E509/$E$503*J$2+F509/$F$503*K$2 -> 9832890
A510: 507 | B510: 39723 | C510: =C509*EXP(('VaR 2 Sim MC'!I$1-'VaR 2 Sim MC'!I$2/2)*1+'VaR 2 Sim MC'!I$3*_xlfn.NORM.S.INV(RAND())*SQRT(1)) -> 11140.818 | D510: =D509*EXP(('VaR 2 Sim MC'!J$1-'VaR 2 Sim MC'!J$2/2)*1+'VaR 2 Sim MC'!J$3*_xlfn.NORM.S.INV(RAND())*SQRT(1)) -> 8866.8763 | E510: =E509*EXP(('VaR 2 Sim MC'!K$1-'VaR 2 Sim MC'!K$2/2)*1+'VaR 2 Sim MC'!K$3*_xlfn.NORM.S.INV(RAND())*SQRT(1)) -> 6040.7574 | F510: =F509*EXP(('VaR 2 Sim MC'!L$1-'VaR 2 Sim MC'!L$2/2)*1+'VaR 2 Sim MC'!L$3*_xlfn.NORM.S.INV(RAND())*SQRT(1)) -> 110.74355 | G510: =C510/$C$503*H$2+D510/$D$503*I$2+E510/$E$503*J$2+F510/$F$503*K$2 -> 9751433.2
A511: 508 | B511: 39724 | C511: =C510*EXP(('VaR 2 Sim MC'!I$1-'VaR 2 Sim MC'!I$2/2)*1+'VaR 2 Sim MC'!I$3*_xlfn.NORM.S.INV(RAND())*SQRT(1)) -> 11148.125 | D511: =D510*EXP(('VaR 2 Sim MC'!J$1-'VaR 2 Sim MC'!J$2/2)*1+'VaR 2 Sim MC'!J$3*_xlfn.NORM.S.INV(RAND())*SQRT(1)) -> 9136.0502 | E511: =E510*EXP(('VaR 2 Sim MC'!K$1-'VaR 2 Sim MC'!K$2/2)*1+'VaR 2 Sim MC'!K$3*_xlfn.NORM.S.INV(RAND())*SQRT(1)) -> 5983.3824 | F511: =F510*EXP(('VaR 2 Sim MC'!L$1-'VaR 2 Sim MC'!L$2/2)*1+'VaR 2 Sim MC'!L$3*_xlfn.NORM.S.INV(RAND())*SQRT(1)) -> 109.95731 | G511: =C511/$C$503*H$2+D511/$D$503*I$2+E511/$E$503*J$2+F511/$F$503*K$2 -> 9815011.4
A512: 509 | B512: 39725 | C512: =C511*EXP(('VaR 2 Sim MC'!I$1-'VaR 2 Sim MC'!I$2/2)*1+'VaR 2 Sim MC'!I$3*_xlfn.NORM.S.INV(RAND())*SQRT(1)) -> 11237.281 | D512: =D511*EXP(('VaR 2 Sim MC'!J$1-'VaR 2 Sim MC'!J$2/2)*1+'VaR 2 Sim MC'!J$3*_xlfn.NORM.S.INV(RAND())*SQRT(1)) -> 9386.9724 | E512: =E511*EXP(('VaR 2 Sim MC'!K$1-'VaR 2 Sim MC'!K$2/2)*1+'VaR 2 Sim MC'!K$3*_xlfn.NORM.S.INV(RAND())*SQRT(1)) -> 5946.9617 | F512: =F511*EXP(('VaR 2 Sim MC'!L$1-'VaR 2 Sim MC'!L$2/2)*1+'VaR 2 Sim MC'!L$3*_xlfn.NORM.S.INV(RAND())*SQRT(1)) -> 112.66912 | G512: =C512/$C$503*H$2+D512/$D$503*I$2+E512/$E$503*J$2+F512/$F$503*K$2 -> 9967979.4
A513: 510 | B513: 39726 | C513: =C512*EXP(('VaR 2 Sim MC'!I$1-'VaR 2 Sim MC'!I$2/2)*1+'VaR 2 Sim MC'!I$3*_xlfn.NORM.S.INV(RAND())*SQRT(1)) -> 11375.384 | D513: =D512*EXP(('VaR 2 Sim MC'!J$1-'VaR 2 Sim MC'!J$2/2)*1+'VaR 2 Sim MC'!J$3*_xlfn.NORM.S.INV(RAND())*SQRT(1)) -> 9299.2083 | E513: =E512*EXP(('VaR 2 Sim MC'!K$1-'VaR 2 Sim MC'!K$2/2)*1+'VaR 2 Sim MC'!K$3*_xlfn.NORM.S.INV(RAND())*SQRT(1)) -> 6006.0615 | F513: =F512*EXP(('VaR 2 Sim MC'!L$1-'VaR 2 Sim MC'!L$2/2)*1+'VaR 2 Sim MC'!L$3*_xlfn.NORM.S.INV(RAND())*SQRT(1)) -> 113.23501 | G513: =C513/$C$503*H$2+D513/$D$503*I$2+E513/$E$503*J$2+F513/$F$503*K$2 -> 10010235
A514: 511 | B514: 39727 | C514: =C513*EXP(('VaR 2 Sim MC'!I$1-'VaR 2 Sim MC'!I$2/2)*1+'VaR 2 Sim MC'!I$3*_xlfn.NORM.S.INV(RAND())*SQRT(1)) -> 11627.595 | D514: =D513*EXP(('VaR 2 Sim MC'!J$1-'VaR 2 Sim MC'!J$2/2)*1+'VaR 2 Sim MC'!J$3*_xlfn.NORM.S.INV(RAND())*SQRT(1)) -> 9322.8515 | E514: =E513*EXP(('VaR 2 Sim MC'!K$1-'VaR 2 Sim MC'!K$2/2)*1+'VaR 2 Sim MC'!K$3*_xlfn.NORM.S.INV(RAND())*SQRT(1)) -> 6118.3381 | F514: =F513*EXP(('VaR 2 Sim MC'!L$1-'VaR 2 Sim MC'!L$2/2)*1+'VaR 2 Sim MC'!L$3*_xlfn.NORM.S.INV(RAND())*SQRT(1)) -> 114.52498 | G514: =C514/$C$503*H$2+D514/$D$503*I$2+E514/$E$503*J$2+F514/$F$503*K$2 -> 10150128
A515: 512 | B515: 39728 | C515: =C514*EXP(('VaR 2 Sim MC'!I$1-'VaR 2 Sim MC'!I$2/2)*1+'VaR 2 Sim MC'!I$3*_xlfn.NORM.S.INV(RAND())*SQRT(1)) -> 11565.786 | D515: =D514*EXP(('VaR 2 Sim MC'!J$1-'VaR 2 Sim MC'!J$2/2)*1+'VaR 2 Sim MC'!J$3*_xlfn.NORM.S.INV(RAND())*SQRT(1)) -> 9202.632 | E515: =E514*EXP(('VaR 2 Sim MC'!K$1-'VaR 2 Sim MC'!K$2/2)*1+'VaR 2 Sim MC'!K$3*_xlfn.NORM.S.INV(RAND())*SQRT(1)) -> 6107.8784 | F515: =F514*EXP(('VaR 2 Sim MC'!L$1-'VaR 2 Sim MC'!L$2/2)*1+'VaR 2 Sim MC'!L$3*_xlfn.NORM.S.INV(RAND())*SQRT(1)) -> 112.32117 | G515: =C515/$C$503*H$2+D515/$D$503*I$2+E515/$E$503*J$2+F515/$F$503*K$2 -> 10049374
... A590: 587 | B590: 39803 | C590: =C589*EXP(('VaR 2 Sim MC'!I$1-'VaR 2 Sim MC'!I$2/2)*1+'VaR 2 Sim MC'!I$3*_xlfn.NORM.S.INV(RAND())*SQRT(1)) -> 11142.586 | D590: =D589*EXP(('VaR 2 Sim MC'!J$1-'VaR 2 Sim MC'!J$2/2)*1+'VaR 2 Sim MC'!J$3*_xlfn.NORM.S.INV(RAND())*SQRT(1)) -> 9188.4182 | E590: =E589*EXP(('VaR 2 Sim MC'!K$1-'VaR 2 Sim MC'!K$2/2)*1+'VaR 2 Sim MC'!K$3*_xlfn.NORM.S.INV(RAND())*SQRT(1)) -> 6597.533 | F590: =F589*EXP(('VaR 2 Sim MC'!L$1-'VaR 2 Sim MC'!L$2/2)*1+'VaR 2 Sim MC'!L$3*_xlfn.NORM.S.INV(RAND())*SQRT(1)) -> 111.35056 | G590: =C590/$C$503*H$2+D590/$D$503*I$2+E590/$E$503*J$2+F590/$F$503*K$2 -> 9953114.9
A591: 588 | B591: 39804 | C591: =C590*EXP(('VaR 2 Sim MC'!I$1-'VaR 2 Sim MC'!I$2/2)*1+'VaR 2 Sim MC'!I$3*_xlfn.NORM.S.INV(RAND())*SQRT(1)) -> 11298.645 | D591: =D590*EXP(('VaR 2 Sim MC'!J$1-'VaR 2 Sim MC'!J$2/2)*1+'VaR 2 Sim MC'!J$3*_xlfn.NORM.S.INV(RAND())*SQRT(1)) -> 9001.1123 | E591: =E590*EXP(('VaR 2 Sim MC'!K$1-'VaR 2 Sim MC'!K$2/2)*1+'VaR 2 Sim MC'!K$3*_xlfn.NORM.S.INV(RAND())*SQRT(1)) -> 6682.268 | F591: =F590*EXP(('VaR 2 Sim MC'!L$1-'VaR 2 Sim MC'!L$2/2)*1+'VaR 2 Sim MC'!L$3*_xlfn.NORM.S.INV(RAND())*SQRT(1)) -> 112.85967 | G591: =C591/$C$503*H$2+D591/$D$503*I$2+E591/$E$503*J$2+F591/$F$503*K$2 -> 9991634.3 | H591: .
A592: 589 | B592: 39805 | C592: =C591*EXP(('VaR 2 Sim MC'!I$1-'VaR 2 Sim MC'!I$2/2)*1+'VaR 2 Sim MC'!I$3*_xlfn.NORM.S.INV(RAND())*SQRT(1)) -> 11296.947 | D592: =D591*EXP(('VaR 2 Sim MC'!J$1-'VaR 2 Sim MC'!J$2/2)*1+'VaR 2 Sim MC'!J$3*_xlfn.NORM.S.INV(RAND())*SQRT(1)) -> 8993.9203 | E592: =E591*EXP(('VaR 2 Sim MC'!K$1-'VaR 2 Sim MC'!K$2/2)*1+'VaR 2 Sim MC'!K$3*_xlfn.NORM.S.INV(RAND())*SQRT(1)) -> 6709.202 | F592: =F591*EXP(('VaR 2 Sim MC'!L$1-'VaR 2 Sim MC'!L$2/2)*1+'VaR 2 Sim MC'!L$3*_xlfn.NORM.S.INV(RAND())*SQRT(1)) -> 111.62539 | G592: =C592/$C$503*H$2+D592/$D$503*I$2+E592/$E$503*J$2+F592/$F$503*K$2 -> 9971234.4
A593: 590 | B593: 39806 | C593: =C592*EXP(('VaR 2 Sim MC'!I$1-'VaR 2 Sim MC'!I$2/2)*1+'VaR 2 Sim MC'!I$3*_xlfn.NORM.S.INV(RAND())*SQRT(1)) -> 11413.048 | D593: =D592*EXP(('VaR 2 Sim MC'!J$1-'VaR 2 Sim MC'!J$2/2)*1+'VaR 2 Sim MC'!J$3*_xlfn.NORM.S.INV(RAND())*SQRT(1)) -> 9161.9391 | E593: =E592*EXP(('VaR 2 Sim MC'!K$1-'VaR 2 Sim MC'!K$2/2)*1+'VaR 2 Sim MC'!K$3*_xlfn.NORM.S.INV(RAND())*SQRT(1)) -> 6774.9455 | F593: =F592*EXP(('VaR 2 Sim MC'!L$1-'VaR 2 Sim MC'!L$2/2)*1+'VaR 2 Sim MC'!L$3*_xlfn.NORM.S.INV(RAND())*SQRT(1)) -> 112.37636 | G593: =C593/$C$503*H$2+D593/$D$503*I$2+E593/$E$503*J$2+F593/$F$503*K$2 -> 10089791
A594: 591 | B594: 39807 | C594: =C593*EXP(('VaR 2 Sim MC'!I$1-'VaR 2 Sim MC'!I$2/2)*1+'VaR 2 Sim MC'!I$3*_xlfn.NORM.S.INV(RAND())*SQRT(1)) -> 11266.196 | D594: =D593*EXP(('VaR 2 Sim MC'!J$1-'VaR 2 Sim MC'!J$2/2)*1+'VaR 2 Sim MC'!J$3*_xlfn.NORM.S.INV(RAND())*SQRT(1)) -> 8996.2117 | E594: =E593*EXP(('VaR 2 Sim MC'!K$1-'VaR 2 Sim MC'!K$2/2)*1+'VaR 2 Sim MC'!K$3*_xlfn.NORM.S.INV(RAND())*SQRT(1)) -> 6733.7267 | F594: =F593*EXP(('VaR 2 Sim MC'!L$1-'VaR 2 Sim MC'!L$2/2)*1+'VaR 2 Sim MC'!L$3*_xlfn.NORM.S.INV(RAND())*SQRT(1)) -> 114.26899 | G594: =C594/$C$503*H$2+D594/$D$503*I$2+E594/$E$503*J$2+F594/$F$503*K$2 -> 10011609
A595: 592 | B595: 39808 | C595: =C594*EXP(('VaR 2 Sim MC'!I$1-'VaR 2 Sim MC'!I$2/2)*1+'VaR 2 Sim MC'!I$3*_xlfn.NORM.S.INV(RAND())*SQRT(1)) -> 11279.413 | D595: =D594*EXP(('VaR 2 Sim MC'!J$1-'VaR 2 Sim MC'!J$2/2)*1+'VaR 2 Sim MC'!J$3*_xlfn.NORM.S.INV(RAND())*SQRT(1)) -> 8945.3418 | E595: =E594*EXP(('VaR 2 Sim MC'!K$1-'VaR 2 Sim MC'!K$2/2)*1+'VaR 2 Sim MC'!K$3*_xlfn.NORM.S.INV(RAND())*SQRT(1)) -> 6802.8843 | F595: =F594*EXP(('VaR 2 Sim MC'!L$1-'VaR 2 Sim MC'!L$2/2)*1+'VaR 2 Sim MC'!L$3*_xlfn.NORM.S.INV(RAND())*SQRT(1)) -> 115.2957 | G595: =C595/$C$503*H$2+D595/$D$503*I$2+E595/$E$503*J$2+F595/$F$503*K$2 -> 10029863
A596: 593 | B596: 39809 | C596: =C595*EXP(('VaR 2 Sim MC'!I$1-'VaR 2 Sim MC'!I$2/2)*1+'VaR 2 Sim MC'!I$3*_xlfn.NORM.S.INV(RAND())*SQRT(1)) -> 11330.554 | D596: =D595*EXP(('VaR 2 Sim MC'!J$1-'VaR 2 Sim MC'!J$2/2)*1+'VaR 2 Sim MC'!J$3*_xlfn.NORM.S.INV(RAND())*SQRT(1)) -> 8935.9724 | E596: =E595*EXP(('VaR 2 Sim MC'!K$1-'VaR 2 Sim MC'!K$2/2)*1+'VaR 2 Sim MC'!K$3*_xlfn.NORM.S.INV(RAND())*SQRT(1)) -> 6800.0499 | F596: =F595*EXP(('VaR 2 Sim MC'!L$1-'VaR 2 Sim MC'!L$2/2)*1+'VaR 2 Sim MC'!L$3*_xlfn.NORM.S.INV(RAND())*SQRT(1)) -> 116.63265 | G596: =C596/$C$503*H$2+D596/$D$503*I$2+E596/$E$503*J$2+F596/$F$503*K$2 -> 10068738
A597: 594 | B597: 39810 | C597: =C596*EXP(('VaR 2 Sim MC'!I$1-'VaR 2 Sim MC'!I$2/2)*1+'VaR 2 Sim MC'!I$3*_xlfn.NORM.S.INV(RAND())*SQRT(1)) -> 11326.37 | D597: =D596*EXP(('VaR 2 Sim MC'!J$1-'VaR 2 Sim MC'!J$2/2)*1+'VaR 2 Sim MC'!J$3*_xlfn.NORM.S.INV(RAND())*SQRT(1)) -> 8663.9507 | E597: =E596*EXP(('VaR 2 Sim MC'!K$1-'VaR 2 Sim MC'!K$2/2)*1+'VaR 2 Sim MC'!K$3*_xlfn.NORM.S.INV(RAND())*SQRT(1)) -> 6776.2086 | F597: =F596*EXP(('VaR 2 Sim MC'!L$1-'VaR 2 Sim MC'!L$2/2)*1+'VaR 2 Sim MC'!L$3*_xlfn.NORM.S.INV(RAND())*SQRT(1)) -> 114.94479 | G597: =C597/$C$503*H$2+D597/$D$503*I$2+E597/$E$503*J$2+F597/$F$503*K$2 -> 9948445.7
A598: 595 | B598: 39811 | C598: =C597*EXP(('VaR 2 Sim MC'!I$1-'VaR 2 Sim MC'!I$2/2)*1+'VaR 2 Sim MC'!I$3*_xlfn.NORM.S.INV(RAND())*SQRT(1)) -> 11348.229 | D598: =D597*EXP(('VaR 2 Sim MC'!J$1-'VaR 2 Sim MC'!J$2/2)*1+'VaR 2 Sim MC'!J$3*_xlfn.NORM.S.INV(RAND())*SQRT(1)) -> 8655.8743 | E598: =E597*EXP(('VaR 2 Sim MC'!K$1-'VaR 2 Sim MC'!K$2/2)*1+'VaR 2 Sim MC'!K$3*_xlfn.NORM.S.INV(RAND())*SQRT(1)) -> 6556.6266 | F598: =F597*EXP(('VaR 2 Sim MC'!L$1-'VaR 2 Sim MC'!L$2/2)*1+'VaR 2 Sim MC'!L$3*_xlfn.NORM.S.INV(RAND())*SQRT(1)) -> 116.60785 | G598: =C598/$C$503*H$2+D598/$D$503*I$2+E598/$E$503*J$2+F598/$F$503*K$2 -> 9947921.7
A599: 596 | B599: 39812 | C599: =C598*EXP(('VaR 2 Sim MC'!I$1-'VaR 2 Sim MC'!I$2/2)*1+'VaR 2 Sim MC'!I$3*_xlfn.NORM.S.INV(RAND())*SQRT(1)) -> 11285.171 | D599: =D598*EXP(('VaR 2 Sim MC'!J$1-'VaR 2 Sim MC'!J$2/2)*1+'VaR 2 Sim MC'!J$3*_xlfn.NORM.S.INV(RAND())*SQRT(1)) -> 8624.9074 | E599: =E598*EXP(('VaR 2 Sim MC'!K$1-'VaR 2 Sim MC'!K$2/2)*1+'VaR 2 Sim MC'!K$3*_xlfn.NORM.S.INV(RAND())*SQRT(1)) -> 6737.7403 | F599: =F598*EXP(('VaR 2 Sim MC'!L$1-'VaR 2 Sim MC'!L$2/2)*1+'VaR 2 Sim MC'!L$3*_xlfn.NORM.S.INV(RAND())*SQRT(1)) -> 114.6436 | G599: =C599/$C$503*H$2+D599/$D$503*I$2+E599/$E$503*J$2+F599/$F$503*K$2 -> 9909749.7
A600: 597 | B600: 39813 | C600: =C599*EXP(('VaR 2 Sim MC'!I$1-'VaR 2 Sim MC'!I$2/2)*1+'VaR 2 Sim MC'!I$3*_xlfn.NORM.S.INV(RAND())*SQRT(1)) -> 11293.656 | D600: =D599*EXP(('VaR 2 Sim MC'!J$1-'VaR 2 Sim MC'!J$2/2)*1+'VaR 2 Sim MC'!J$3*_xlfn.NORM.S.INV(RAND())*SQRT(1)) -> 8775.7851 | E600: =E599*EXP(('VaR 2 Sim MC'!K$1-'VaR 2 Sim MC'!K$2/2)*1+'VaR 2 Sim MC'!K$3*_xlfn.NORM.S.INV(RAND())*SQRT(1)) -> 6660.4932 | F600: =F599*EXP(('VaR 2 Sim MC'!L$1-'VaR 2 Sim MC'!L$2/2)*1+'VaR 2 Sim MC'!L$3*_xlfn.NORM.S.INV(RAND())*SQRT(1)) -> 113.55919 | G600: =C600/$C$503*H$2+D600/$D$503*I$2+E600/$E$503*J$2+F600/$F$503*K$2 -> 9928297.1
G603: 39813
F604: 1 | G604: 9874742
...

Sheet VaR Paramétrico
A1: Rendimientos diarios de los activos
H2: Matriz de correlaciones de los rendimientos de los activos
A3: Scenario | B3: DJIA | C3: FTSE 100 | D3: CAC 40 | E3: Nikkei 225
A4: 1 | B4: =Data!D5/Data!D4 -> 0.99591867 | C4: =Data!H5/Data!H4 -> 0.99680539 | D4: =Data!L5/Data!L4 -> 1.0006695 | E4: =Data!P5/Data!P4 -> 1.0197867 | I4: DJIA | J4: FTSE 100 | K4: CAC 40 | L4: Nikkei 225
A5: 2 | B5: =Data!D6/Data!D5 -> 0.99128212 | C5: =Data!H6/Data!H5 -> 1.008027 | D5: =Data!L6/Data!L5 -> 1.0150323 | E5: =Data!P6/Data!P5 -> 1.0116197 | H5: DJIA | I5: 1
A6: 3 | B6: =Data!D7/Data!D6 -> 1.0043508 | C6: =Data!H7/Data!H6 -> 0.98492294 | D6: =Data!L7/Data!L6 -> 0.98199668 | E6: =Data!P7/Data!P6 -> 0.99628366 | H6: FTSE 100 | I6: 0.48910594 | J6: 1
A7: 4 | B7: =Data!D8/Data!D7 -> 0.9967324 | C7: =Data!H8/Data!H7 -> 1.0021805 | D7: =Data!L8/Data!L7 -> 1.0011449 | E7: =Data!P8/Data!P7 -> 0.99012238 | H7: CAC 40 | I7: 0.49570963 | J7: 0.91810825 | K7: 1
A8: 5 | B8: =Data!D9/Data!D8 -> 1.0008883 | C8: =Data!H9/Data!H8 -> 1.0062292 | D8: =Data!L9/Data!L8 -> 1.0105116 | E8: =Data!P9/Data!P8 -> 1.0154414 | H8: Nikkei 225 | I8: -0.061899208 | J8: 0.20094221 | K8: 0.21095096 | L8: 1
A9: 6 | B9: =Data!D10/Data!D9 -> 1.0119293 | C9: =Data!H10/Data!H9 -> 1.0062978 | D9: =Data!L10/Data!L9 -> 1.0169906 | E9: =Data!P10/Data!P9 -> 1.0011161
A10: 7 | B10: =Data!D11/Data!D10 -> 1.0086249 | C10: =Data!H11/Data!H10 -> 1.0021531 | D10: =Data!L11/Data!L10 -> 1.0095215 | E10: =Data!P11/Data!P10 -> 1.0182398
A11: 8 | B11: =Data!D12/Data!D11 -> 1.0006921 | C11: =Data!H12/Data!H11 -> 0.99701052 | D11: =Data!L12/Data!L11 -> 1.0021098 | E11: =Data!P12/Data!P11 -> 0.99901366 | H11: aT = | I11: 4000000 | J11: 3000000 | K11: 1000000 | L11: 2000000
A12: 9 | B12: =Data!D13/Data!D12 -> 1.0041032 | C12: =Data!H13/Data!H12 -> 0.99337365 | D12: =Data!L13/Data!L12 -> 0.99502209 | E12: =Data!P13/Data!P12 -> 1.0034903
